Workbook
Name CLASS: #REF!
Name CLASS: #REF!
Name CLASS: #REF!
Name CLASS: #REF!
Name CLASS: #REF!
Name CODE: #REF!
Name CODE: #REF!
Name CODE: #REF!
Name CODE: #REF!
Name CODE: #REF!
Name CODE: #REF!
Name CODE: #REF!
Name CODE: #REF!
Name COURSE_NAME: #REF!
Name COURSE_NAME: #REF!
Name COURSE_NAME: #REF!
Name COURSE_NAME: #REF!
Name COURSE_NAME: #REF!
Name COURSE_NAME: #REF!
Name COURSE_NAME: #REF!
Name COURSE_NAME: #REF!
Name EA: #REF!
Name EXAMINER: #REF!
Name EXAMINER: #REF!
Name EXAMINER: #REF!
Name EXAMINER: #REF!
Name EXAMINER: #REF!
Name EXAMINER: #REF!
Name EXAMINER: #REF!
Name EXAMINER: #REF!
Name hy: #REF!
Name hy: #REF!
Name po: #REF!
Name po: #REF!
Name room_no: #REF!
Name room_no: #REF!
Name room_no: #REF!
Name ROOM_NO.: #REF!
Name ROOM_NO.: #REF!
Name ROOM_NO.: #REF!
Name ROOM_NO.: #REF!
Name ROOM_NO.: #REF!
Name ROOM_NO.: #REF!
Name ROOM_NO.: #REF!
Name STDS: #REF!
Name STDS: #REF!
Name STDS: #REF!
Name STDS: #REF!
Name STDS: #REF!
Name STDS: #REF!
Name STDS: #REF!
Name STDS: #REF!
Name TO_PRT: #REF!
Name TO_PRT: #REF!
Name TO_PRT: #REF!
Name TO_PRT: #REF!
Name TO_PRT: #REF!
Name TO_PRT: #REF!
Name TO_PRT: #REF!
Name TO_PRT: #REF!

Sheet TT
I1: =_xlfn.CONCAT(A1,",",D1) -> , | J1: =#N/A -> #N/A
I2: , | J2: =#N/A -> #N/A
A3: Tuesday, 7 April 2026 | I3: Tuesday, 7 April 2026, | J3: =#N/A -> #N/A
A4: Session, 1 (8:30 AM - 10:30 AM) | I4: Session, 1 (8:30 AM - 10:30 AM), | J4: =#N/A -> #N/A
A5: CODE | B5: COURSE NAME | C5: EXAMINER | D5: CLASS | E5: # STDS | F5: ROOM NO. | G5: TO PRT | I5: CODE ,CLASS | J5: =#N/A -> #N/A
A6: MATH 251 | B6: =IFERROR(VLOOKUP(I6:I15,Lecturers!A2:F596,6,FALSE),0) -> DIFFERENTIAL EQUATIONS | C6: =IFERROR(VLOOKUP(I6:I15,Lecturers!A2:F596,2,FALSE),0) -> Boateng Maxwell Akwasi | D6: ED2-MARI | E6: =IFERROR(VLOOKUP(I6:I15,Lecturers!A2:F596,3,FALSE),0) -> 37 | F6: NAF1 | G6: =E6*1.1 -> 40.7 | H6: 37 | I6: =_xlfn.CONCAT(A6,",",D6) -> MATH 251,ED2-MARI | J6: 74
A7: MATH 251 | B7: DIFFERENTIAL EQUATIONS | C7: Boateng Maxwell Akwasi | D7: ED2-ME | E7: 242 | F7: NEB-TF/NEB-SF/NEB-FF1/NEB-FF2 | G7: =E7*1.1 -> 266.2 | H7: 80/80/52/30 | I7: MATH 251,ED2-ME | J7: =#N/A -> #N/A
A8: CHE 153 | B8: ORGANIC CHEMISTRY FOR ENGINEERS | C8: Laryea Michael Konney | D8: ED1-CHE | E8: 120 | F8: VSLA/303/LT/RMA/206 | G8: =E8*1.1 -> 132 | H8: 35/25/20/20/20 | I8: CHE 153,ED1-CHE | J8: 129
A9: CHE 153 | B9: ORGANIC CHEMISTRY FOR ENGINEERS | C9: Laryea Michael Konney | D9: ED1-PCE | E9: 58 | F9: A110/EA | G9: =E9*1.1 -> 63.8 | H9: 30/28 | I9: CHE 153,ED1-PCE | J9: 61
A10: PE 153 | B10: ORGANIC CHEMISTRY FOR ENGINEERS | C10: Laryea Michael Konney | D10: ED1-PE | E10: 130 | F10: VSLA/303/LT/206/RMA | G10: =E10*1.1 -> 143 | H10: 40/26/22/22/20 | I10: PE 153,ED1-PE | J10: 107
A11: CHE 471 | B11: PHARMACEUTICAL TECHNOLOGY | C11: Johnson Raphael | D11: ED4-PCE | E11: 36 | F11: NAF1 | G11: =E11*1.1 -> 39.6 | H11: 36 | I11: =_xlfn.CONCAT(A11,",",D11) -> CHE 471,ED4-PCE | J11: 45
A12: PCE 359 | B12: PETROLEUM FLUID PROPERTIES | C12: Adenutsi Caspar Daniel | D12: ED3-PCE | E12: 51 | F12: A110/EA | G12: =E12*1.1 -> 56.1 | H12: 26/25 | I12: =_xlfn.CONCAT(A12,",",D12) -> PCE 359,ED3-PCE | J12: 99
A13: CENG 291 | B13: ENGINEERING IN SOCIETY | C13: Odame Prince | D13: ED2-BME | E13: 80 | F13: PB214/PB008/PB208 | G13: =E13*1.1 -> 88 | H13: 30/25/25 | I13: CENG 291,ED2-BME
A14: CENG 291 | B14: ENGINEERING IN SOCIETY | C14: Odame Prince | D14: ED2-COE | E14: 255 | F14: PB201/PB008/PB208/PB001/PB020/PB014/PB214 | G14: =E14*1.1 -> 280.5 | H14: 39/30/30/39/39/39/39 | I14: =_xlfn.CONCAT(A14,",",D14) -> CENG 291,ED2-COE | J14: 240
A15: EE 261 | B15: DC MACHINES | C15: Effah Francis Boafo | D15: ED2-EE | E15: 345 | F15: NEB-TF/NEB-SF/NEB-FF1/PB001/PB020/PB014/PB201 | G15: =E15*1.1 -> 379.5 | H15: 72/72/49/38/38/38/38 | I15: EE 261,ED2-EE | J15: 129
D16: Total T1-1 | E16: =SUM(E6:E15) -> 1354 | I16: =_xlfn.CONCAT(A16,",",D16) -> ,Total T1-1 | J16: =#N/A -> #N/A
I17: , | J17: =#N/A -> #N/A
I18: , | J18: =#N/A -> #N/A
A19: Tuesday, 7 April 2026 | I19: Tuesday, 7 April 2026, | J19: =#N/A -> #N/A
A20: Session, 2 (12:00 PM - 2:00 PM) | I20: Session, 2 (12:00 PM - 2:00 PM), | J20: =#N/A -> #N/A
A21: CODE | B21: COURSE NAME | C21: EXAMINER | D21: CLASS | E21: # STDS | F21: ROOM NO. | G21: TO PRT | I21: CODE ,CLASS | J21: =#N/A -> #N/A
A22: COE 363 | B22: =IFERROR(VLOOKUP(I22:I32,Lecturers!A2:F596,6,FALSE),0) -> DATA STRUCTURES AND ALGORITHMS | C22: =VLOOKUP(I22:I32,Lecturers!A2:G598,2,FALSE) -> Adjaidoo Theresa-Samuelle Maame Atwemaah | D22: ED3-COE | E22: =IFERROR(VLOOKUP(I22:I32,Lecturers!A2:F596,3,FALSE),0) -> 270 | F22: COMPUTER BASED | G22: =E22*1.1 -> 297 | I22: COE 363,ED3-COE
A23: CE 255 | B23: THEORY OF STRUCTURES | C23: Ampofo James Wiafe | D23: ED2-CE | E23: 255 | F23: PB001/PB020/PB014/PB201/PB214/PB008/PB208 | G23: =E23*1.1 -> 280.5 | H23: 40/40/40/40/40/28/27 | I23: CE 255,ED2-CE | J23: 285
A24: CE 255 | B24: THEORY OF STRUCTURES | C24: Ampofo James Wiafe | D24: ED2-GEOL | E24: 150 | F24: VSLA/303/LT/206/RMA/RMB | G24: =E24*1.1 -> 165 | H24: 40/30/20/20/20/20 | I24: CE 255,ED2-GEOL | J24: 151
A25: CE 367 | B25: HIGHWAY AND TRANSPORTATION ENGINEERING I | C25: Ababio-Donkor Augustus | D25: ED3-GEOM | E25: 125 | F25: NEB-TF/NEB-FF1 | G25: =E25*1.1 -> 137.5 | H25: 75/50 | I25: =_xlfn.CONCAT(A25,",",D25) -> CE 367,ED3-GEOM | J25: 150
A26: ME 161 | B26: BASIC MECHANICS | C26: Opoku Richard | D26: ED1-CE | E26: 245 | F26: PB001/PB020/PB014/PB201/PB214/PB208/PB008 | G26: =E26*1.1 -> 269.5 | H26: 38/38/38/38/38/28/27 | I26: =_xlfn.CONCAT(A26,",",D26) -> ME 161,ED1-CE | J26: 105
A27: GED 151 | B27: BASIC GEOLOGY | C27: Gawu Simon Kafui Yawo | D27: ED1-GEOL | E27: 125 | F27: A110/EA/VCR/NAF1 | G27: =E27*1.1 -> 137.5 | H27: 30/30/25/40 | I27: =_xlfn.CONCAT(A27,",",D27) -> GED 151,ED1-GEOL | J27: 105
A28: CENG 291 | B28: ENGINEERING IN SOCIETY | C28: Koomson Bennetta | D28: ED2-MSE | E28: 80 | F28: VSLA/303/RMA | G28: =E28*1.1 -> 88 | H28: 35/25/20 | I28: =_xlfn.CONCAT(A28,",",D28) -> CENG 291,ED2-MSE | J28: 148
A29: CENG 291 | B29: ENGINEERING IN SOCIETY | C29: Koomson Bennetta | D29: ED2-METE | E29: 59 | F29: NAF1/A110 | G29: =E29*1.1 -> 64.9 | H29: 35/24 | I29: =_xlfn.CONCAT(A29,",",D29) -> CENG 291,ED2-METE | J29: 148
A30: COE 475P | B30: COMPUTER NETWORKING | C30: Adrah Charles Mawutor | D30: ED4-EE | E30: 215 | F30: NEB-TF/NEB-SF/NEB-FF1/NEB-FF2 | G30: =E30*1.1 -> 236.5 | H30: 70/70/45/30 | I30: =_xlfn.CONCAT(A30,",",D30) -> COE 475P,ED4-EE
A31: ME 499 | B31: OPERATIONS RESEARCH | C31: Mensah Lena Dzifa | D31: ED4-AERO | E31: 2 | F31: NEB-FF2 | G31: =E31*1.1 -> 2.2 | H31: 2 | I31: ME 499,ED4-AERO
A32: IE 351 | B32: OPERATIONS RESEARCH I | C32: Mensah Lena Dzifa | D32: ED3-IND | E32: 72 | F32: NEB-SF | G32: =E32*1.1 -> 79.2 | H32: 72 | I32: =_xlfn.CONCAT(A32,",",D32) -> IE 351,ED3-IND | J32: 143
D33: Total T1-2 | E33: =SUM(E23:E32) -> 1328 | I33: ,Total T1-2 | J33: =#N/A -> #N/A
I34: , | J34: =#N/A -> #N/A
I35: , | J35: =#N/A -> #N/A
A36: Tuesday, 7 April 2026 | I36: Tuesday, 7 April 2026, | J36: =#N/A -> #N/A
A37: Session, 3 (3:00 PM - 5:00 PM) | I37: Session, 3 (3:00 PM - 5:00 PM), | J37: =#N/A -> #N/A
A38: CODE | B38: COURSE NAME | C38: EXAMINER | D38: CLASS | E38: # STDS | F38: ROOM NO. | G38: TO PRT | I38: CODE ,CLASS | J38: =#N/A -> #N/A
A39: CE 477 | B39: =IFERROR(VLOOKUP(I39:I49,Lecturers!A2:F596,6,FALSE),0) -> GEOTECHNICAL ENGINEERING I | C39: =VLOOKUP(I39:I49,Lecturers!A2:G598,2,FALSE) -> Ayeh Felix Jojo Fianko | D39: ED4-CE | E39: =IFERROR(VLOOKUP(I39:I49,Lecturers!A2:F596,3,FALSE),0) -> 35 | F39: VSLA | G39: =E39*1.1 -> 38.5 | H39: 35 | I39: CE 477,ED4-CE
A40: CE 477 | B40: GEOTECHNICAL ENGINEERING I | C40: Ampadu Samuel Innocent Kofi | D40: ED4-GEOL | E40: 95 | F40: NAF1/A110/EA/VCR | G40: =E40*1.1 -> 104.5 | H40: 30/23/22/20 | I40: CE 477,ED4-GEOL | J40: 134
...

Sheet Lecturers
A1: Unnamed: 0 | B1: Unnamed: 6 | C1: No of students | E1: BSC. AEROSPACE ENG., Year 1 | F1: Unnamed: 4
A2: =_xlfn.CONCAT(E2,",",D2) -> AERO 157,ED1-AERO | B2: Oppong David Kofi | C2: 70 | D2: ED1-AERO | E2: AERO 157 | F2: INTRODUCTION TO AVIATION TECHNOLOGY
A3: CE 155,ED1-AERO | B3: Appiah-Brempong Miriam | C3: 70 | D3: =D2 -> ED1-AERO | E3: CE 155 | F3: ENVIRONMENTAL STUDIES
A4: EE 151,ED1-AERO | B4: Oteng Gyasi Kwame | C4: 70 | D4: =D3 -> ED1-AERO | E4: EE 151 | F4: APPLIED ELECTRICITY
A5: ENGL 157,ED1-AERO | B5: Appiah Franklin Benjamin | C5: 70 | D5: =D4 -> ED1-AERO | E5: ENGL 157 | F5: COMMUNICATION SKILLS I
A6: MATH 151,ED1-AERO | B6: Fosu Gabriel Obed | C6: 70 | D6: =D5 -> ED1-AERO | E6: MATH 151 | F6: ALGEBRA
A7: ME 157,ED1-AERO | B7: Sackey Michael Nii | C7: 70 | D7: =D6 -> ED1-AERO | E7: ME 157 | F7: INTRODUCTION TO INFORMATION TECHNOLOGY
A8: ME 159,ED1-AERO | B8: Oppong Tawiah Peter | C8: 70 | D8: =D7 -> ED1-AERO | E8: ME 159 | F8: TECHNICAL DRAWING
A9: ME 281,ED2-AERO | B9: Amoabeng Kofi Owura | C9: 75 | D9: ED2-AERO | E9: ME 281 | F9: ENGINEERING MATERIALS I
A10: CENG 291,ED2-AERO | B10: Oppong David Kofi | C10: 75 | D10: =D9 -> ED2-AERO | E10: CENG 291 | F10: ENGINEERING IN SOCIETY
A11: AERO 293,ED2-AERO | B11: Oppong David Kofi | C11: 75 | D11: =D10 -> ED2-AERO | E11: AERO 293 | F11: AEROSPACE ENGINEERING VACATION TRAINING I
A12: ME 255,ED2-AERO | B12: Agyei Agyemang Anthony | C12: 75 | D12: =D11 -> ED2-AERO | E12: ME 255 | F12: STRENGTH OF MATERIALS I
A13: ENGL 263,ED2-AERO | B13: Yeboah Philomena Ama Okyeso | C13: 75 | D13: =D12 -> ED2-AERO | E13: ENGL 263 | F13: LITERATURE IN ENGLISH I
A14: MATH 251,ED2-AERO | B14: Wireko Fredrick Asenso | C14: 75 | D14: =D13 -> ED2-AERO | E14: MATH 251 | F14: DIFFERENTIAL EQUATIONS
A15: ME 251,ED2-AERO | B15: Fiagbe Yesuenyeagbe Atsu Kwabla | C15: 75 | D15: =D14 -> ED2-AERO | E15: ME 251 | F15: INTRODUCTION TO FLUID MECHANICS
A16: ME 261,ED2-AERO | B16: Ampofo Joshua | C16: 75 | D16: =D15 -> ED2-AERO | E16: ME 261 | F16: ENGINEERING MECHANICS II:DYNAMICS
A17: ME 295,ED2-AERO | B17: David Kofi Oppong | C17: 75 | D17: =D16 -> ED2-AERO | E17: ME 295 | F17: MECHANICAL ENGINEERING LAB. I
A18: ECON 151,ED3-AERO | B18: Takyi Paul Owusu | C18: 76 | D18: ED3-AERO | E18: ECON 151 | F18: INTRODUCTION TO ECONOMICS I
A19: AERO 393,ED3-AERO | B19: Oppong David Kofi | C19: 76 | D19: =D18 -> ED3-AERO | E19: AERO 393 | F19: AEROSPACE ENGINEERING VACATION TRAINING II
A20: AERO 351,ED3-AERO | B20: Bofah Kwasi Kete | C20: 76 | D20: =D19 -> ED3-AERO | E20: AERO 351 | F20: AERODYNAMICS I
A21: AERO 391,ED3-AERO | B21: Kwasi Kete Bofah | C21: 76 | D21: =D20 -> ED3-AERO | E21: AERO 391 | F21: AEROSPACE INDUSTRY AND ENGINEERING
A22: AERO 395,ED3-AERO | B22: Oppong David Kofi | C22: 76 | D22: =D21 -> ED3-AERO | E22: AERO 395 | F22: AEROSPACE ENGINEERING LAB. I
A23: MATH 351,ED3-AERO | B23: Borkor Reindorf Nartey | C23: 76 | D23: =D22 -> ED3-AERO | E23: MATH 351 | F23: NUMERICAL ANALYSIS
A24: STAT 253,ED3-AERO | B24: Carole Fredua Amoako-Yirenkyi | C24: 76 | D24: =D23 -> ED3-AERO | E24: STAT 253 | F24: PROBABILITY AND STATISTICS
A25: ME 363,ED3-AERO | B25: Faisal Wahib Adam | C25: 76 | D25: =D24 -> ED3-AERO | E25: ME 363 | F25: AUTOMATIC CONTROL I
A26: AERO 473,ED4-AERO | B26: Oppong David Kofi | C26: 61 | D26: ED4-AERO | E26: AERO 473 | F26: AEROSPACE VEHICLE DESIGN
A27: AERO 483,ED4-AERO | B27: Oppong David Kofi | C27: 61 | D27: =D26 -> ED4-AERO | E27: AERO 483 | F27: AVIONICS
A28: AERO 491,ED4-AERO | B28: Takyi Gabriel | C28: 61 | D28: =D27 -> ED4-AERO | E28: AERO 491 | F28: AVIATION BUSINESS MANAGEMENT
A29: AERO 493,ED4-AERO | B29: Oppong David Kofi | C29: 61 | D29: =D28 -> ED4-AERO | E29: AERO 493 | F29: AEROSPACE ENGINEERING VACATION TRAINING III
A30: AERO 495,ED4-AERO | B30: Oppong Tawiah Peter | C30: 61 | D30: =D29 -> ED4-AERO | E30: AERO 495 | F30: AIRCRAFT MAINTENANCE ENGINEERING
A31: AERO 497,ED4-AERO | B31: Tay Godwin Fabiola Kwaku | C31: 61 | D31: =D30 -> ED4-AERO | E31: AERO 497 | F31: PROJECT I
A32: ME 451,ED4-AERO | B32: Opoku Richard | C32: 53 | D32: =D31 -> ED4-AERO | E32: ME 451 | F32: BEHAVIOUR OF REAL FLUIDS
A33: ME 473,ED4-AERO | B33: Afriyie Nyarko Frank Kwabena | C33: 7 | D33: =D32 -> ED4-AERO | E33: ME 473 | F33: COMPUTER AIDED DESIGN AND MANUFACTURING
A34: ME 499,ED4-AERO | B34: Mensah Lena Dzifa | C34: 2 | D34: =D33 -> ED4-AERO | E34: ME 499 | F34: OPERATIONS RESEARCH
A36: AE 153,ED1-AE | B36: Bessah Enoch | C36: 128 | D36: ED1-AE | E36: AE 153 | F36: AGRIC. METEOROLOGY AND CLIMATOLOGY
A37: EE 151,ED1-AE | B37: Prah II Nicholas Kwesi | C37: 135 | D37: =D36 -> ED1-AE | E37: EE 151 | F37: APPLIED ELECTRICITY
A38: ENGL 157,ED1-AE | B38: Yeboah Philomena Ama Okyeso | C38: 128 | D38: =D37 -> ED1-AE | E38: ENGL 157 | F38: COMMUNICATION SKILLS I
A39: MATH 151,ED1-AE | B39: Asamoah Joshua Kiddy Kwasi | C39: 128 | D39: =D38 -> ED1-AE | E39: MATH 151 | F39: ALGEBRA
A40: ME 159,ED1-AE | B40: Aveyire Joseph | C40: 128 | D40: =D39 -> ED1-AE | E40: ME 159 | F40: TECHNICAL DRAWING
A41: ME 195,ED1-AE | B41: Oppong David Kofi | C41: 128 | D41: =D40 -> ED1-AE | E41: ME 195 | F41: ENGINEERING TECHNOLOGY I
...

Sheet TALLY
B1: T1 | E1: W1 | H1: H1 | K1: F1 | N1: M2 | Q1: T2 | T1: W2 | W1: H2 | Z1: F2 | AC1: M3 | AF1: T3 | AI1: W3 | AL1: H3 | AO1: F3
B2: S1 | C2: S2 | D2: S3 | E2: S1 | F2: S2 | G2: S3 | H2: S1 | I2: S2 | J2: S3 | K2: S1 | L2: S2 | M2: S3 | N2: S1 | O2: S2 | P2: S3 | Q2: S1 | R2: S2 | S2: S3 | T2: S1 | U2: S2 | V2: S3 | W2: S1 | X2: S2 | Y2: S3 | Z2: S1 | AA2: S2 | AB2: S3 | AC2: S1 | AD2: S2 | AE2: S3 | AF2: S1 | AG2: S2 | AH2: S3 | AI2: S1 | AJ2: S2 | AK2: S3 | AL2: S1 | AM2: S2 | AN2: S3 | AO2: S1 | AP2: S2 | AQ2: S3 | AS2: T1 | AT2: W1 | AU2: H1 | AV2: F1 | AW2: M2 | AX2: T2 | AY2: W2 | AZ2: H2 | BA2: F2 | BB2: M3 | BC2: T3 | BD2: W3 | BE2: H3 | BF2: F3
A3: ED1-AE | B3: =COUNTIF(TT!$D$6:$D$15,TALLY!A3) -> 0 | C3: =COUNTIF(TT!$D$22:$D$32,TALLY!A3) -> 0 | D3: =COUNTIF(TT!$D$39:$D$49,TALLY!A3) -> 1 | E3: =COUNTIF(TT!$D$57:$D$67,TALLY!A3) -> 0 | F3: =COUNTIF(TT!$D$74:$D$86,TALLY!A3) -> 0 | G3: =COUNTIF(TT!$D$93:$D$107,TALLY!A3) -> 0 | H3: =COUNTIF(TT!$D$113:$D$129,TALLY!A3) -> 0 | I3: =COUNTIF(TT!$D$135:$D$155,TALLY!A3) -> 0 | J3: =COUNTIF(TT!$D$162:$D$173,TALLY!A3) -> 0 | K3: =COUNTIF(TT!$D$180:$D$199,TALLY!A3) -> 1 | L3: =COUNTIF(TT!$D$207:$D$215,TALLY!A3) -> 0 | M3: =COUNTIF(TT!$D$224:$D$231,TALLY!A3) -> 0 | N3: =COUNTIF(TT!$D$237:$D$249,TALLY!A3) -> 1 | O3: =COUNTIF(TT!$D$256:$D$264,TALLY!A3) -> 0 | P3: =COUNTIF(TT!$D$271:$D$286,TALLY!A3) -> 0 | Q3: =COUNTIF(TT!$D$293:$D$300,TALLY!A3) -> 0 | R3: =COUNTIF(TT!$D$307:$D$319,TALLY!A3) -> 1 | S3: =COUNTIF(TT!$D$326:$D$334,TALLY!A3) -> 0 | T3: =COUNTIF(TT!$D$341:$D$350,TALLY!A3) -> 0 | U3: =COUNTIF(TT!$D$357:$D$366,TALLY!A3) -> 0 | V3: =COUNTIF(TT!$D$373:$D$383,TALLY!A3) -> 0 | W3: =COUNTIF(TT!$D$390:$D$405,TALLY!A3) -> 1 | X3: =COUNTIF(TT!$D$412:$D$423,TALLY!A3) -> 0 | Y3: =COUNTIF(TT!$D$430:$D$438,TALLY!A3) -> 0 | Z3: =COUNTIF(TT!$D$443:$D$457,TALLY!A3) -> 0 | AA3: =COUNTIF(TT!$D$464:$D$474,TALLY!A3) -> 0 | AB3: =COUNTIF(TT!$D$481:$D$494,TALLY!A3) -> 0 | AC3: =COUNTIF(TT!$D$503:$D$522,TALLY!A3) -> 0 | AD3: =COUNTIF(TT!$D$529:$D$541,TALLY!A3) -> 0 | AE3: =COUNTIF(TT!$D$548:$D$561,TALLY!A3) -> 1 | AF3: =COUNTIF(TT!$D$574:$D$584,TALLY!A3) -> 0 | AG3: =COUNTIF(TT!$D$591:$D$601,TALLY!A3) -> 0 | AH3: =COUNTIF(TT!$D$608:$D$619,TALLY!A3) -> 0 | AI3: =COUNTIF(TT!$D$628:$D$647,TALLY!A3) -> 1 | AJ3: =COUNTIF(TT!$D$654:$D$668,TALLY!A3) -> 0 | AK3: =COUNTIF(TT!$D$675:$D$685,TALLY!A3) -> 0 | AL3: =COUNTIF(TT!$D$692:$D$702,TALLY!A3) -> 0 | AM3: =COUNTIF(TT!$D$709:$D$721,TALLY!A3) -> 0 | AN3: =COUNTIF(TT!$D$728:$D$737,TALLY!A3) -> 0 | AO3: =COUNTIF(TT!$D$744:$D$753,TALLY!A3) -> 0 | AP3: =COUNTIF(TT!$D$759:$D$774,TALLY!A3) -> 0 | AQ3: =COUNTIF(TT!$D$781:$D$789,TALLY!A3) -> 0 | AR3: ED1-AE | AS3: =SUM($B3:$D3) -> 1 | AT3: =SUM(E3:G3) -> 0 | AU3: =SUM(H3:J3) -> 0 | AV3: =SUM(K3:M3) -> 1 | AW3: =SUM(N3:P3) -> 1 | AX3: =SUM($Q3:$S3) -> 1 | AY3: =SUM(T3:V3) -> 0 | AZ3: =SUM(W3:Y3) -> 1 | BA3: =SUM(Z3:AB3) -> 0 | BB3: =SUM(AC3:AE3) -> 1 | BC3: =SUM(AF3:AH3) -> 0 | BD3: =SUM(AI3:AK3) -> 1 | BE3: =SUM(AL3:AN3) -> 0 | BF3: =SUM(AO3:AQ3) -> 0 | BG3: =SUM(AS3:BF3) -> 7
A4: ED1-AERO | B4: =COUNTIF(TT!$D$6:$D$15,TALLY!A4) -> 0 | C4: =COUNTIF(TT!$D$22:$D$32,TALLY!A4) -> 0 | D4: =COUNTIF(TT!$D$39:$D$49,TALLY!A4) -> 1 | E4: =COUNTIF(TT!$D$57:$D$67,TALLY!A4) -> 0 | F4: =COUNTIF(TT!$D$74:$D$86,TALLY!A4) -> 0 | G4: =COUNTIF(TT!$D$93:$D$107,TALLY!A4) -> 0 | H4: =COUNTIF(TT!$D$113:$D$129,TALLY!A4) -> 0 | I4: =COUNTIF(TT!$D$135:$D$155,TALLY!A4) -> 0 | J4: =COUNTIF(TT!$D$162:$D$173,TALLY!A4) -> 0 | K4: =COUNTIF(TT!$D$180:$D$199,TALLY!A4) -> 1 | L4: =COUNTIF(TT!$D$207:$D$215,TALLY!A4) -> 0 | M4: =COUNTIF(TT!$D$224:$D$231,TALLY!A4) -> 0 | N4: =COUNTIF(TT!$D$237:$D$249,TALLY!A4) -> 0 | O4: =COUNTIF(TT!$D$256:$D$264,TALLY!A4) -> 0 | P4: =COUNTIF(TT!$D$271:$D$286,TALLY!A4) -> 0 | Q4: =COUNTIF(TT!$D$293:$D$300,TALLY!A4) -> 0 | R4: =COUNTIF(TT!$D$307:$D$319,TALLY!A4) -> 1 | S4: =COUNTIF(TT!$D$326:$D$334,TALLY!A4) -> 0 | T4: =COUNTIF(TT!$D$341:$D$350,TALLY!A4) -> 0 | U4: =COUNTIF(TT!$D$357:$D$366,TALLY!A4) -> 0 | V4: =COUNTIF(TT!$D$373:$D$383,TALLY!A4) -> 0 | W4: =COUNTIF(TT!$D$390:$D$405,TALLY!A4) -> 0 | X4: =COUNTIF(TT!$D$412:$D$423,TALLY!A4) -> 0 | Y4: =COUNTIF(TT!$D$430:$D$438,TALLY!A4) -> 0 | Z4: =COUNTIF(TT!$D$443:$D$457,TALLY!A4) -> 1 | AA4: =COUNTIF(TT!$D$464:$D$474,TALLY!A4) -> 0 | AB4: =COUNTIF(TT!$D$481:$D$494,TALLY!A4) -> 0 | AC4: =COUNTIF(TT!$D$503:$D$522,TALLY!A4) -> 0 | AD4: =COUNTIF(TT!$D$529:$D$541,TALLY!A4) -> 0 | AE4: =COUNTIF(TT!$D$548:$D$561,TALLY!A4) -> 0 | AF4: =COUNTIF(TT!$D$574:$D$584,TALLY!A4) -> 0 | AG4: =COUNTIF(TT!$D$591:$D$601,TALLY!A4) -> 0 | AH4: =COUNTIF(TT!$D$608:$D$619,TALLY!A4) -> 0 | AI4: =COUNTIF(TT!$D$628:$D$647,TALLY!A4) -> 0 | AJ4: =COUNTIF(TT!$D$654:$D$668,TALLY!A4) -> 0 | AK4: =COUNTIF(TT!$D$675:$D$685,TALLY!A4) -> 1 | AL4: =COUNTIF(TT!$D$692:$D$702,TALLY!A4) -> 0 | AM4: =COUNTIF(TT!$D$709:$D$721,TALLY!A4) -> 0 | AN4: =COUNTIF(TT!$D$728:$D$737,TALLY!A4) -> 0 | AO4: =COUNTIF(TT!$D$744:$D$753,TALLY!A4) -> 0 | AP4: =COUNTIF(TT!$D$759:$D$774,TALLY!A4) -> 1 | AQ4: =COUNTIF(TT!$D$781:$D$789,TALLY!A4) -> 0 | AR4: ED1-AERO | AS4: =SUM($B4:$D4) -> 1 | AT4: =SUM(E4:G4) -> 0 | AU4: =SUM(H4:J4) -> 0 | AV4: =SUM(K4:M4) -> 1 | AW4: =SUM(N4:P4) -> 0 | AX4: =SUM($Q4:$S4) -> 1 | AY4: =SUM(T4:V4) -> 0 | AZ4: =SUM(W4:Y4) -> 0 | BA4: =SUM(Z4:AB4) -> 1 | BB4: =SUM(AC4:AE4) -> 0 | BC4: =SUM(AF4:AH4) -> 0 | BD4: =SUM(AI4:AK4) -> 1 | BE4: =SUM(AL4:AN4) -> 0 | BF4: =SUM(AO4:AQ4) -> 1 | BG4: =SUM(AS4:BF4) -> 6
A5: ED1-AUTO | B5: =COUNTIF(TT!$D$6:$D$15,TALLY!A5) -> 0 | C5: =COUNTIF(TT!$D$22:$D$32,TALLY!A5) -> 0 | D5: =COUNTIF(TT!$D$39:$D$49,TALLY!A5) -> 0 | E5: =COUNTIF(TT!$D$57:$D$67,TALLY!A5) -> 0 | F5: =COUNTIF(TT!$D$74:$D$86,TALLY!A5) -> 0 | G5: =COUNTIF(TT!$D$93:$D$107,TALLY!A5) -> 0 | H5: =COUNTIF(TT!$D$113:$D$129,TALLY!A5) -> 1 | I5: =COUNTIF(TT!$D$135:$D$155,TALLY!A5) -> 0 | J5: =COUNTIF(TT!$D$162:$D$173,TALLY!A5) -> 0 | K5: =COUNTIF(TT!$D$180:$D$199,TALLY!A5) -> 0 | L5: =COUNTIF(TT!$D$207:$D$215,TALLY!A5) -> 1 | M5: =COUNTIF(TT!$D$224:$D$231,TALLY!A5) -> 0 | N5: =COUNTIF(TT!$D$237:$D$249,TALLY!A5) -> 0 | O5: =COUNTIF(TT!$D$256:$D$264,TALLY!A5) -> 0 | P5: =COUNTIF(TT!$D$271:$D$286,TALLY!A5) -> 0 | Q5: =COUNTIF(TT!$D$293:$D$300,TALLY!A5) -> 0 | R5: =COUNTIF(TT!$D$307:$D$319,TALLY!A5) -> 1 | S5: =COUNTIF(TT!$D$326:$D$334,TALLY!A5) -> 0 | T5: =COUNTIF(TT!$D$341:$D$350,TALLY!A5) -> 0 | U5: =COUNTIF(TT!$D$357:$D$366,TALLY!A5) -> 0 | V5: =COUNTIF(TT!$D$373:$D$383,TALLY!A5) -> 0 | W5: =COUNTIF(TT!$D$390:$D$405,TALLY!A5) -> 1 | X5: =COUNTIF(TT!$D$412:$D$423,TALLY!A5) -> 0 | Y5: =COUNTIF(TT!$D$430:$D$438,TALLY!A5) -> 0 | Z5: =COUNTIF(TT!$D$443:$D$457,TALLY!A5) -> 0 | AA5: =COUNTIF(TT!$D$464:$D$474,TALLY!A5) -> 0 | AB5: =COUNTIF(TT!$D$481:$D$494,TALLY!A5) -> 0 | AC5: =COUNTIF(TT!$D$503:$D$522,TALLY!A5) -> 0 | AD5: =COUNTIF(TT!$D$529:$D$541,TALLY!A5) -> 1 | AE5: =COUNTIF(TT!$D$548:$D$561,TALLY!A5) -> 0 | AF5: =COUNTIF(TT!$D$574:$D$584,TALLY!A5) -> 0 | AG5: =COUNTIF(TT!$D$591:$D$601,TALLY!A5) -> 0 | AH5: =COUNTIF(TT!$D$608:$D$619,TALLY!A5) -> 0 | AI5: =COUNTIF(TT!$D$628:$D$647,TALLY!A5) -> 0 | AJ5: =COUNTIF(TT!$D$654:$D$668,TALLY!A5) -> 0 | AK5: =COUNTIF(TT!$D$675:$D$685,TALLY!A5) -> 1 | AL5: =COUNTIF(TT!$D$692:$D$702,TALLY!A5) -> 0 | AM5: =COUNTIF(TT!$D$709:$D$721,TALLY!A5) -> 0 | AN5: =COUNTIF(TT!$D$728:$D$737,TALLY!A5) -> 0 | AO5: =COUNTIF(TT!$D$744:$D$753,TALLY!A5) -> 1 | AP5: =COUNTIF(TT!$D$759:$D$774,TALLY!A5) -> 0 | AQ5: =COUNTIF(TT!$D$781:$D$789,TALLY!A5) -> 0 | AR5: ED1-AUTO | AS5: =SUM($B5:$D5) -> 0 | AT5: =SUM(E5:G5) -> 0 | AU5: =SUM(H5:J5) -> 1 | AV5: =SUM(K5:M5) -> 1 | AW5: =SUM(N5:P5) -> 0 | AX5: =SUM($Q5:$S5) -> 1 | AY5: =SUM(T5:V5) -> 0 | AZ5: =SUM(W5:Y5) -> 1 | BA5: =SUM(Z5:AB5) -> 0 | BB5: =SUM(AC5:AE5) -> 1 | BC5: =SUM(AF5:AH5) -> 0 | BD5: =SUM(AI5:AK5) -> 1 | BE5: =SUM(AL5:AN5) -> 0 | BF5: =SUM(AO5:AQ5) -> 1 | BG5: =SUM(AS5:BF5) -> 7
A6: ED1-BME | B6: =COUNTIF(TT!$D$6:$D$15,TALLY!A6) -> 0 | C6: =COUNTIF(TT!$D$22:$D$32,TALLY!A6) -> 0 | D6: =COUNTIF(TT!$D$39:$D$49,TALLY!A6) -> 0 | E6: =COUNTIF(TT!$D$57:$D$67,TALLY!A6) -> 0 | F6: =COUNTIF(TT!$D$74:$D$86,TALLY!A6) -> 1 | G6: =COUNTIF(TT!$D$93:$D$107,TALLY!A6) -> 0 | H6: =COUNTIF(TT!$D$113:$D$129,TALLY!A6) -> 0 | I6: =COUNTIF(TT!$D$135:$D$155,TALLY!A6) -> 0 | J6: =COUNTIF(TT!$D$162:$D$173,TALLY!A6) -> 0 | K6: =COUNTIF(TT!$D$180:$D$199,TALLY!A6) -> 1 | L6: =COUNTIF(TT!$D$207:$D$215,TALLY!A6) -> 0 | M6: =COUNTIF(TT!$D$224:$D$231,TALLY!A6) -> 0 | N6: =COUNTIF(TT!$D$237:$D$249,TALLY!A6) -> 0 | O6: =COUNTIF(TT!$D$256:$D$264,TALLY!A6) -> 0 | P6: =COUNTIF(TT!$D$271:$D$286,TALLY!A6) -> 0 | Q6: =COUNTIF(TT!$D$293:$D$300,TALLY!A6) -> 1 | R6: =COUNTIF(TT!$D$307:$D$319,TALLY!A6) -> 0 | S6: =COUNTIF(TT!$D$326:$D$334,TALLY!A6) -> 0 | T6: =COUNTIF(TT!$D$341:$D$350,TALLY!A6) -> 0 | U6: =COUNTIF(TT!$D$357:$D$366,TALLY!A6) -> 0 | V6: =COUNTIF(TT!$D$373:$D$383,TALLY!A6) -> 1 | W6: =COUNTIF(TT!$D$390:$D$405,TALLY!A6) -> 0 | X6: =COUNTIF(TT!$D$412:$D$423,TALLY!A6) -> 0 | Y6: =COUNTIF(TT!$D$430:$D$438,TALLY!A6) -> 0 | Z6: =COUNTIF(TT!$D$443:$D$457,TALLY!A6) -> 0 | AA6: =COUNTIF(TT!$D$464:$D$474,TALLY!A6) -> 0 | AB6: =COUNTIF(TT!$D$481:$D$494,TALLY!A6) -> 0 | AC6: =COUNTIF(TT!$D$503:$D$522,TALLY!A6) -> 0 | AD6: =COUNTIF(TT!$D$529:$D$541,TALLY!A6) -> 0 | AE6: =COUNTIF(TT!$D$548:$D$561,TALLY!A6) -> 0 | AF6: =COUNTIF(TT!$D$574:$D$584,TALLY!A6) -> 0 | AG6: =COUNTIF(TT!$D$591:$D$601,TALLY!A6) -> 0 | AH6: =COUNTIF(TT!$D$608:$D$619,TALLY!A6) -> 0 | AI6: =COUNTIF(TT!$D$628:$D$647,TALLY!A6) -> 0 | AJ6: =COUNTIF(TT!$D$654:$D$668,TALLY!A6) -> 1 | AK6: =COUNTIF(TT!$D$675:$D$685,TALLY!A6) -> 0 | AL6: =COUNTIF(TT!$D$692:$D$702,TALLY!A6) -> 0 | AM6: =COUNTIF(TT!$D$709:$D$721,TALLY!A6) -> 1 | AN6: =COUNTIF(TT!$D$728:$D$737,TALLY!A6) -> 0 | AO6: =COUNTIF(TT!$D$744:$D$753,TALLY!A6) -> 0 | AP6: =COUNTIF(TT!$D$759:$D$774,TALLY!A6) -> 0 | AQ6: =COUNTIF(TT!$D$781:$D$789,TALLY!A6) -> 0 | AR6: ED1-BME | AS6: =SUM($B6:$D6) -> 0 | AT6: =SUM(E6:G6) -> 1 | AU6: =SUM(H6:J6) -> 0 | AV6: =SUM(K6:M6) -> 1 | AW6: =SUM(N6:P6) -> 0 | AX6: =SUM($Q6:$S6) -> 1 | AY6: =SUM(T6:V6) -> 1 | AZ6: =SUM(W6:Y6) -> 0 | BA6: =SUM(Z6:AB6) -> 0 | BB6: =SUM(AC6:AE6) -> 0 | BC6: =SUM(AF6:AH6) -> 0 | BD6: =SUM(AI6:AK6) -> 1 | BE6: =SUM(AL6:AN6) -> 1 | BF6: =SUM(AO6:AQ6) -> 0 | BG6: =SUM(AS6:BF6) -> 6
A7: ED1-CE | B7: =COUNTIF(TT!$D$6:$D$15,TALLY!A7) -> 0 | C7: =COUNTIF(TT!$D$22:$D$32,TALLY!A7) -> 1 | D7: =COUNTIF(TT!$D$39:$D$49,TALLY!A7) -> 0 | E7: =COUNTIF(TT!$D$57:$D$67,TALLY!A7) -> 0 | F7: =COUNTIF(TT!$D$74:$D$86,TALLY!A7) -> 0 | G7: =COUNTIF(TT!$D$93:$D$107,TALLY!A7) -> 0 | H7: =COUNTIF(TT!$D$113:$D$129,TALLY!A7) -> 1 | I7: =COUNTIF(TT!$D$135:$D$155,TALLY!A7) -> 0 | J7: =COUNTIF(TT!$D$162:$D$173,TALLY!A7) -> 0 | K7: =COUNTIF(TT!$D$180:$D$199,TALLY!A7) -> 0 | L7: =COUNTIF(TT!$D$207:$D$215,TALLY!A7) -> 1 | M7: =COUNTIF(TT!$D$224:$D$231,TALLY!A7) -> 0 | N7: =COUNTIF(TT!$D$237:$D$249,TALLY!A7) -> 1 | O7: =COUNTIF(TT!$D$256:$D$264,TALLY!A7) -> 0 | P7: =COUNTIF(TT!$D$271:$D$286,TALLY!A7) -> 0 | Q7: =COUNTIF(TT!$D$293:$D$300,TALLY!A7) -> 0 | R7: =COUNTIF(TT!$D$307:$D$319,TALLY!A7) -> 0 | S7: =COUNTIF(TT!$D$326:$D$334,TALLY!A7) -> 0 | T7: =COUNTIF(TT!$D$341:$D$350,TALLY!A7) -> 1 | U7: =COUNTIF(TT!$D$357:$D$366,TALLY!A7) -> 0 | V7: =COUNTIF(TT!$D$373:$D$383,TALLY!A7) -> 0 | W7: =COUNTIF(TT!$D$390:$D$405,TALLY!A7) -> 0 | X7: =COUNTIF(TT!$D$412:$D$423,TALLY!A7) -> 0 | Y7: =COUNTIF(TT!$D$430:$D$438,TALLY!A7) -> 1 | Z7: =COUNTIF(TT!$D$443:$D$457,TALLY!A7) -> 0 | AA7: =COUNTIF(TT!$D$464:$D$474,TALLY!A7) -> 0 | AB7: =COUNTIF(TT!$D$481:$D$494,TALLY!A7) -> 0 | AC7: =COUNTIF(TT!$D$503:$D$522,TALLY!A7) -> 1 | AD7: =COUNTIF(TT!$D$529:$D$541,TALLY!A7) -> 0 | AE7: =COUNTIF(TT!$D$548:$D$561,TALLY!A7) -> 0 | AF7: =COUNTIF(TT!$D$574:$D$584,TALLY!A7) -> 0 | AG7: =COUNTIF(TT!$D$591:$D$601,TALLY!A7) -> 0 | AH7: =COUNTIF(TT!$D$608:$D$619,TALLY!A7) -> 0 | AI7: =COUNTIF(TT!$D$628:$D$647,TALLY!A7) -> 1 | AJ7: =COUNTIF(TT!$D$654:$D$668,TALLY!A7) -> 0 | AK7: =COUNTIF(TT!$D$675:$D$685,TALLY!A7) -> 0 | AL7: =COUNTIF(TT!$D$692:$D$702,TALLY!A7) -> 0 | AM7: =COUNTIF(TT!$D$709:$D$721,TALLY!A7) -> 1 | AN7: =COUNTIF(TT!$D$728:$D$737,TALLY!A7) -> 0 | AO7: =COUNTIF(TT!$D$744:$D$753,TALLY!A7) -> 0 | AP7: =COUNTIF(TT!$D$759:$D$774,TALLY!A7) -> 0 | AQ7: =COUNTIF(TT!$D$781:$D$789,TALLY!A7) -> 0 | AR7: ED1-CE | AS7: =SUM($B7:$D7) -> 1 | AT7: =SUM(E7:G7) -> 0 | AU7: =SUM(H7:J7) -> 1 | AV7: =SUM(K7:M7) -> 1 | AW7: =SUM(N7:P7) -> 1 | AX7: =SUM($Q7:$S7) -> 0 | AY7: =SUM(T7:V7) -> 1 | AZ7: =SUM(W7:Y7) -> 1 | BA7: =SUM(Z7:AB7) -> 0 | BB7: =SUM(AC7:AE7) -> 1 | BC7: =SUM(AF7:AH7) -> 0 | BD7: =SUM(AI7:AK7) -> 1 | BE7: =SUM(AL7:AN7) -> 1 | BF7: =SUM(AO7:AQ7) -> 0 | BG7: =SUM(AS7:BF7) -> 9
A8: ED1-CHE | B8: =COUNTIF(TT!$D$6:$D$15,TALLY!A8) -> 1 | C8: =COUNTIF(TT!$D$22:$D$32,TALLY!A8) -> 0 | D8: =COUNTIF(TT!$D$39:$D$49,TALLY!A8) -> 0 | E8: =COUNTIF(TT!$D$57:$D$67,TALLY!A8) -> 0 | F8: =COUNTIF(TT!$D$74:$D$86,TALLY!A8) -> 0 | G8: =COUNTIF(TT!$D$93:$D$107,TALLY!A8) -> 0 | H8: =COUNTIF(TT!$D$113:$D$129,TALLY!A8) -> 0 | I8: =COUNTIF(TT!$D$135:$D$155,TALLY!A8) -> 0 | J8: =COUNTIF(TT!$D$162:$D$173,TALLY!A8) -> 0 | K8: =COUNTIF(TT!$D$180:$D$199,TALLY!A8) -> 1 | L8: =COUNTIF(TT!$D$207:$D$215,TALLY!A8) -> 0 | M8: =COUNTIF(TT!$D$224:$D$231,TALLY!A8) -> 0 | N8: =COUNTIF(TT!$D$237:$D$249,TALLY!A8) -> 1 | O8: =COUNTIF(TT!$D$256:$D$264,TALLY!A8) -> 0 | P8: =COUNTIF(TT!$D$271:$D$286,TALLY!A8) -> 0 | Q8: =COUNTIF(TT!$D$293:$D$300,TALLY!A8) -> 0 | R8: =COUNTIF(TT!$D$307:$D$319,TALLY!A8) -> 1 | S8: =COUNTIF(TT!$D$326:$D$334,TALLY!A8) -> 0 | T8: =COUNTIF(TT!$D$341:$D$350,TALLY!A8) -> 0 | U8: =COUNTIF(TT!$D$357:$D$366,TALLY!A8) -> 0 | V8: =COUNTIF(TT!$D$373:$D$383,TALLY!A8) -> 0 | W8: =COUNTIF(TT!$D$390:$D$405,TALLY!A8) -> 0 | X8: =COUNTIF(TT!$D$412:$D$423,TALLY!A8) -> 0 | Y8: =COUNTIF(TT!$D$430:$D$438,TALLY!A8) -> 0 | Z8: =COUNTIF(TT!$D$443:$D$457,TALLY!A8) -> 0 | AA8: =COUNTIF(TT!$D$464:$D$474,TALLY!A8) -> 0 | AB8: =COUNTIF(TT!$D$481:$D$494,TALLY!A8) -> 0 | AC8: =COUNTIF(TT!$D$503:$D$522,TALLY!A8) -> 0 | AD8: =COUNTIF(TT!$D$529:$D$541,TALLY!A8) -> 0 | AE8: =COUNTIF(TT!$D$548:$D$561,TALLY!A8) -> 0 | AF8: =COUNTIF(TT!$D$574:$D$584,TALLY!A8) -> 0 | AG8: =COUNTIF(TT!$D$591:$D$601,TALLY!A8) -> 0 | AH8: =COUNTIF(TT!$D$608:$D$619,TALLY!A8) -> 0 | AI8: =COUNTIF(TT!$D$628:$D$647,TALLY!A8) -> 0 | AJ8: =COUNTIF(TT!$D$654:$D$668,TALLY!A8) -> 1 | AK8: =COUNTIF(TT!$D$675:$D$685,TALLY!A8) -> 0 | AL8: =COUNTIF(TT!$D$692:$D$702,TALLY!A8) -> 1 | AM8: =COUNTIF(TT!$D$709:$D$721,TALLY!A8) -> 0 | AN8: =COUNTIF(TT!$D$728:$D$737,TALLY!A8) -> 0 | AO8: =COUNTIF(TT!$D$744:$D$753,TALLY!A8) -> 0 | AP8: =COUNTIF(TT!$D$759:$D$774,TALLY!A8) -> 1 | AQ8: =COUNTIF(TT!$D$781:$D$789,TALLY!A8) -> 0 | AR8: ED1-CHE | AS8: =SUM($B8:$D8) -> 1 | AT8: =SUM(E8:G8) -> 0 | AU8: =SUM(H8:J8) -> 0 | AV8: =SUM(K8:M8) -> 1 | AW8: =SUM(N8:P8) -> 1 | AX8: =SUM($Q8:$S8) -> 1 | AY8: =SUM(T8:V8) -> 0 | AZ8: =SUM(W8:Y8) -> 0 | BA8: =SUM(Z8:AB8) -> 0 | BB8: =SUM(AC8:AE8) -> 0 | BC8: =SUM(AF8:AH8) -> 0 | BD8: =SUM(AI8:AK8) -> 1 | BE8: =SUM(AL8:AN8) -> 1 | BF8: =SUM(AO8:AQ8) -> 1 | BG8: =SUM(AS8:BF8) -> 7
A9: ED1-COE | B9: =COUNTIF(TT!$D$6:$D$15,TALLY!A9) -> 0 | C9: =COUNTIF(TT!$D$22:$D$32,TALLY!A9) -> 0 | D9: =COUNTIF(TT!$D$39:$D$49,TALLY!A9) -> 1 | E9: =COUNTIF(TT!$D$57:$D$67,TALLY!A9) -> 0 | F9: =COUNTIF(TT!$D$74:$D$86,TALLY!A9) -> 0 | G9: =COUNTIF(TT!$D$93:$D$107,TALLY!A9) -> 0 | H9: =COUNTIF(TT!$D$113:$D$129,TALLY!A9) -> 0 | I9: =COUNTIF(TT!$D$135:$D$155,TALLY!A9) -> 0 | J9: =COUNTIF(TT!$D$162:$D$173,TALLY!A9) -> 0 | K9: =COUNTIF(TT!$D$180:$D$199,TALLY!A9) -> 0 | L9: =COUNTIF(TT!$D$207:$D$215,TALLY!A9) -> 1 | M9: =COUNTIF(TT!$D$224:$D$231,TALLY!A9) -> 0 | N9: =COUNTIF(TT!$D$237:$D$249,TALLY!A9) -> 0 | O9: =COUNTIF(TT!$D$256:$D$264,TALLY!A9) -> 0 | P9: =COUNTIF(TT!$D$271:$D$286,TALLY!A9) -> 0 | Q9: =COUNTIF(TT!$D$293:$D$300,TALLY!A9) -> 1 | R9: =COUNTIF(TT!$D$307:$D$319,TALLY!A9) -> 0 | S9: =COUNTIF(TT!$D$326:$D$334,TALLY!A9) -> 0 | T9: =COUNTIF(TT!$D$341:$D$350,TALLY!A9) -> 0 | U9: =COUNTIF(TT!$D$357:$D$366,TALLY!A9) -> 0 | V9: =COUNTIF(TT!$D$373:$D$383,TALLY!A9) -> 1 | W9: =COUNTIF(TT!$D$390:$D$405,TALLY!A9) -> 0 | X9: =COUNTIF(TT!$D$412:$D$423,TALLY!A9) -> 0 | Y9: =COUNTIF(TT!$D$430:$D$438,TALLY!A9) -> 1 | Z9: =COUNTIF(TT!$D$443:$D$457,TALLY!A9) -> 0 | AA9: =COUNTIF(TT!$D$464:$D$474,TALLY!A9) -> 0 | AB9: =COUNTIF(TT!$D$481:$D$494,TALLY!A9) -> 0 | AC9: =COUNTIF(TT!$D$503:$D$522,TALLY!A9) -> 0 | AD9: =COUNTIF(TT!$D$529:$D$541,TALLY!A9) -> 0 | AE9: =COUNTIF(TT!$D$548:$D$561,TALLY!A9) -> 0 | AF9: =COUNTIF(TT!$D$574:$D$584,TALLY!A9) -> 0 | AG9: =COUNTIF(TT!$D$591:$D$601,TALLY!A9) -> 0 | AH9: =COUNTIF(TT!$D$608:$D$619,TALLY!A9) -> 0 | AI9: =COUNTIF(TT!$D$628:$D$647,TALLY!A9) -> 0 | AJ9: =COUNTIF(TT!$D$654:$D$668,TALLY!A9) -> 1 | AK9: =COUNTIF(TT!$D$675:$D$685,TALLY!A9) -> 0 | AL9: =COUNTIF(TT!$D$692:$D$702,TALLY!A9) -> 0 | AM9: =COUNTIF(TT!$D$709:$D$721,TALLY!A9) -> 0 | AN9: =COUNTIF(TT!$D$728:$D$737,TALLY!A9) -> 0 | AO9: =COUNTIF(TT!$D$744:$D$753,TALLY!A9) -> 0 | AP9: =COUNTIF(TT!$D$759:$D$774,TALLY!A9) -> 0 | AQ9: =COUNTIF(TT!$D$781:$D$789,TALLY!A9) -> 0 | AR9: ED1-COE | AS9: =SUM($B9:$D9) -> 1 | AT9: =SUM(E9:G9) -> 0 | AU9: =SUM(H9:J9) -> 0 | AV9: =SUM(K9:M9) -> 1 | AW9: =SUM(N9:P9) -> 0 | AX9: =SUM($Q9:$S9) -> 1 | AY9: =SUM(T9:V9) -> 1 | AZ9: =SUM(W9:Y9) -> 1 | BA9: =SUM(Z9:AB9) -> 0 | BB9: =SUM(AC9:AE9) -> 0 | BC9: =SUM(AF9:AH9) -> 0 | BD9: =SUM(AI9:AK9) -> 1 | BE9: =SUM(AL9:AN9) -> 0 | BF9: =SUM(AO9:AQ9) -> 0 | BG9: =SUM(AS9:BF9) -> 6
A10: ED1-EE | B10: =COUNTIF(TT!$D$6:$D$15,TALLY!A10) -> 0 | C10: =COUNTIF(TT!$D$22:$D$32,TALLY!A10) -> 0 | D10: =COUNTIF(TT!$D$39:$D$49,TALLY!A10) -> 0 | E10: =COUNTIF(TT!$D$57:$D$67,TALLY!A10) -> 0 | F10: =COUNTIF(TT!$D$74:$D$86,TALLY!A10) -> 0 | G10: =COUNTIF(TT!$D$93:$D$107,TALLY!A10) -> 0 | H10: =COUNTIF(TT!$D$113:$D$129,TALLY!A10) -> 1 | I10: =COUNTIF(TT!$D$135:$D$155,TALLY!A10) -> 0 | J10: =COUNTIF(TT!$D$162:$D$173,TALLY!A10) -> 0 | K10: =COUNTIF(TT!$D$180:$D$199,TALLY!A10) -> 1 | L10: =COUNTIF(TT!$D$207:$D$215,TALLY!A10) -> 0 | M10: =COUNTIF(TT!$D$224:$D$231,TALLY!A10) -> 0 | N10: =COUNTIF(TT!$D$237:$D$249,TALLY!A10) -> 0 | O10: =COUNTIF(TT!$D$256:$D$264,TALLY!A10) -> 1 | P10: =COUNTIF(TT!$D$271:$D$286,TALLY!A10) -> 0 | Q10: =COUNTIF(TT!$D$293:$D$300,TALLY!A10) -> 1 | R10: =COUNTIF(TT!$D$307:$D$319,TALLY!A10) -> 0 | S10: =COUNTIF(TT!$D$326:$D$334,TALLY!A10) -> 0 | T10: =COUNTIF(TT!$D$341:$D$350,TALLY!A10) -> 0 | U10: =COUNTIF(TT!$D$357:$D$366,TALLY!A10) -> 0 | V10: =COUNTIF(TT!$D$373:$D$383,TALLY!A10) -> 0 | W10: =COUNTIF(TT!$D$390:$D$405,TALLY!A10) -> 1 | X10: =COUNTIF(TT!$D$412:$D$423,TALLY!A10) -> 0 | Y10: =COUNTIF(TT!$D$430:$D$438,TALLY!A10) -> 0 | Z10: =COUNTIF(TT!$D$443:$D$457,TALLY!A10) -> 0 | AA10: =COUNTIF(TT!$D$464:$D$474,TALLY!A10) -> 0 | AB10: =COUNTIF(TT!$D$481:$D$494,TALLY!A10) -> 0 | AC10: =COUNTIF(TT!$D$503:$D$522,TALLY!A10) -> 0 | AD10: =COUNTIF(TT!$D$529:$D$541,TALLY!A10) -> 0 | AE10: =COUNTIF(TT!$D$548:$D$561,TALLY!A10) -> 1 | AF10: =COUNTIF(TT!$D$574:$D$584,TALLY!A10) -> 0 | AG10: =COUNTIF(TT!$D$591:$D$601,TALLY!A10) -> 0 | AH10: =COUNTIF(TT!$D$608:$D$619,TALLY!A10) -> 0 | AI10: =COUNTIF(TT!$D$628:$D$647,TALLY!A10) -> 0 | AJ10: =COUNTIF(TT!$D$654:$D$668,TALLY!A10) -> 0 | AK10: =COUNTIF(TT!$D$675:$D$685,TALLY!A10) -> 1 | AL10: =COUNTIF(TT!$D$692:$D$702,TALLY!A10) -> 0 | AM10: =COUNTIF(TT!$D$709:$D$721,TALLY!A10) -> 0 | AN10: =COUNTIF(TT!$D$728:$D$737,TALLY!A10) -> 0 | AO10: =COUNTIF(TT!$D$744:$D$753,TALLY!A10) -> 0 | AP10: =COUNTIF(TT!$D$759:$D$774,TALLY!A10) -> 0 | AQ10: =COUNTIF(TT!$D$781:$D$789,TALLY!A10) -> 0 | AR10: ED1-EE | AS10: =SUM($B10:$D10) -> 0 | AT10: =SUM(E10:G10) -> 0 | AU10: =SUM(H10:J10) -> 1 | AV10: =SUM(K10:M10) -> 1 | AW10: =SUM(N10:P10) -> 1 | AX10: =SUM($Q10:$S10) -> 1 | AY10: =SUM(T10:V10) -> 0 | AZ10: =SUM(W10:Y10) -> 1 | BA10: =SUM(Z10:AB10) -> 0 | BB10: =SUM(AC10:AE10) -> 1 | BC10: =SUM(AF10:AH10) -> 0 | BD10: =SUM(AI10:AK10) -> 1 | BE10: =SUM(AL10:AN10) -> 0 | BF10: =SUM(AO10:AQ10) -> 0 | BG10: =SUM(AS10:BF10) -> 7
A11: ED1-GEOL | B11: =COUNTIF(TT!$D$6:$D$15,TALLY!A11) -> 0 | C11: =COUNTIF(TT!$D$22:$D$32,TALLY!A11) -> 1 | D11: =COUNTIF(TT!$D$39:$D$49,TALLY!A11) -> 0 | E11: =COUNTIF(TT!$D$57:$D$67,TALLY!A11) -> 0 | F11: =COUNTIF(TT!$D$74:$D$86,TALLY!A11) -> 0 | G11: =COUNTIF(TT!$D$93:$D$107,TALLY!A11) -> 0 | H11: =COUNTIF(TT!$D$113:$D$129,TALLY!A11) -> 1 | I11: =COUNTIF(TT!$D$135:$D$155,TALLY!A11) -> 0 | J11: =COUNTIF(TT!$D$162:$D$173,TALLY!A11) -> 0 | K11: =COUNTIF(TT!$D$180:$D$199,TALLY!A11) -> 0 | L11: =COUNTIF(TT!$D$207:$D$215,TALLY!A11) -> 1 | M11: =COUNTIF(TT!$D$224:$D$231,TALLY!A11) -> 0 | N11: =COUNTIF(TT!$D$237:$D$249,TALLY!A11) -> 1 | O11: =COUNTIF(TT!$D$256:$D$264,TALLY!A11) -> 0 | P11: =COUNTIF(TT!$D$271:$D$286,TALLY!A11) -> 0 | Q11: =COUNTIF(TT!$D$293:$D$300,TALLY!A11) -> 0 | R11: =COUNTIF(TT!$D$307:$D$319,TALLY!A11) -> 0 | S11: =COUNTIF(TT!$D$326:$D$334,TALLY!A11) -> 0 | T11: =COUNTIF(TT!$D$341:$D$350,TALLY!A11) -> 0 | U11: =COUNTIF(TT!$D$357:$D$366,TALLY!A11) -> 0 | V11: =COUNTIF(TT!$D$373:$D$383,TALLY!A11) -> 1 | W11: =COUNTIF(TT!$D$390:$D$405,TALLY!A11) -> 0 | X11: =COUNTIF(TT!$D$412:$D$423,TALLY!A11) -> 0 | Y11: =COUNTIF(TT!$D$430:$D$438,TALLY!A11) -> 1 | Z11: =COUNTIF(TT!$D$443:$D$457,TALLY!A11) -> 0 | AA11: =COUNTIF(TT!$D$464:$D$474,TALLY!A11) -> 0 | AB11: =COUNTIF(TT!$D$481:$D$494,TALLY!A11) -> 0 | AC11: =COUNTIF(TT!$D$503:$D$522,TALLY!A11) -> 1 | AD11: =COUNTIF(TT!$D$529:$D$541,TALLY!A11) -> 0 | AE11: =COUNTIF(TT!$D$548:$D$561,TALLY!A11) -> 0 | AF11: =COUNTIF(TT!$D$574:$D$584,TALLY!A11) -> 0 | AG11: =COUNTIF(TT!$D$591:$D$601,TALLY!A11) -> 0 | AH11: =COUNTIF(TT!$D$608:$D$619,TALLY!A11) -> 0 | AI11: =COUNTIF(TT!$D$628:$D$647,TALLY!A11) -> 1 | AJ11: =COUNTIF(TT!$D$654:$D$668,TALLY!A11) -> 0 | AK11: =COUNTIF(TT!$D$675:$D$685,TALLY!A11) -> 0 | AL11: =COUNTIF(TT!$D$692:$D$702,TALLY!A11) -> 0 | AM11: =COUNTIF(TT!$D$709:$D$721,TALLY!A11) -> 1 | AN11: =COUNTIF(TT!$D$728:$D$737,TALLY!A11) -> 0 | AO11: =COUNTIF(TT!$D$744:$D$753,TALLY!A11) -> 0 | AP11: =COUNTIF(TT!$D$759:$D$774,TALLY!A11) -> 1 | AQ11: =COUNTIF(TT!$D$781:$D$789,TALLY!A11) -> 0 | AR11: ED1-GEOL | AS11: =SUM($B11:$D11) -> 1 | AT11: =SUM(E11:G11) -> 0 | AU11: =SUM(H11:J11) -> 1 | AV11: =SUM(K11:M11) -> 1 | AW11: =SUM(N11:P11) -> 1 | AX11: =SUM($Q11:$S11) -> 0 | AY11: =SUM(T11:V11) -> 1 | AZ11: =SUM(W11:Y11) -> 1 | BA11: =SUM(Z11:AB11) -> 0 | BB11: =SUM(AC11:AE11) -> 1 | BC11: =SUM(AF11:AH11) -> 0 | BD11: =SUM(AI11:AK11) -> 1 | BE11: =SUM(AL11:AN11) -> 1 | BF11: =SUM(AO11:AQ11) -> 1 | BG11: =SUM(AS11:BF11) -> 10
A12: ED1-GEOM | B12: =COUNTIF(TT!$D$6:$D$15,TALLY!A12) -> 0 | C12: =COUNTIF(TT!$D$22:$D$32,TALLY!A12) -> 0 | D12: =COUNTIF(TT!$D$39:$D$49,TALLY!A12) -> 0 | E12: =COUNTIF(TT!$D$57:$D$67,TALLY!A12) -> 0 | F12: =COUNTIF(TT!$D$74:$D$86,TALLY!A12) -> 0 | G12: =COUNTIF(TT!$D$93:$D$107,TALLY!A12) -> 0 | H12: =COUNTIF(TT!$D$113:$D$129,TALLY!A12) -> 0 | I12: =COUNTIF(TT!$D$135:$D$155,TALLY!A12) -> 1 | J12: =COUNTIF(TT!$D$162:$D$173,TALLY!A12) -> 0 | K12: =COUNTIF(TT!$D$180:$D$199,TALLY!A12) -> 0 | L12: =COUNTIF(TT!$D$207:$D$215,TALLY!A12) -> 1 | M12: =COUNTIF(TT!$D$224:$D$231,TALLY!A12) -> 0 | N12: =COUNTIF(TT!$D$237:$D$249,TALLY!A12) -> 0 | O12: =COUNTIF(TT!$D$256:$D$264,TALLY!A12) -> 1 | P12: =COUNTIF(TT!$D$271:$D$286,TALLY!A12) -> 0 | Q12: =COUNTIF(TT!$D$293:$D$300,TALLY!A12) -> 0 | R12: =COUNTIF(TT!$D$307:$D$319,TALLY!A12) -> 0 | S12: =COUNTIF(TT!$D$326:$D$334,TALLY!A12) -> 0 | T12: =COUNTIF(TT!$D$341:$D$350,TALLY!A12) -> 0 | U12: =COUNTIF(TT!$D$357:$D$366,TALLY!A12) -> 0 | V12: =COUNTIF(TT!$D$373:$D$383,TALLY!A12) -> 0 | W12: =COUNTIF(TT!$D$390:$D$405,TALLY!A12) -> 0 | X12: =COUNTIF(TT!$D$412:$D$423,TALLY!A12) -> 0 | Y12: =COUNTIF(TT!$D$430:$D$438,TALLY!A12) -> 0 | Z12: =COUNTIF(TT!$D$443:$D$457,TALLY!A12) -> 1 | AA12: =COUNTIF(TT!$D$464:$D$474,TALLY!A12) -> 0 | AB12: =COUNTIF(TT!$D$481:$D$494,TALLY!A12) -> 0 | AC12: =COUNTIF(TT!$D$503:$D$522,TALLY!A12) -> 0 | AD12: =COUNTIF(TT!$D$529:$D$541,TALLY!A12) -> 1 | AE12: =COUNTIF(TT!$D$548:$D$561,TALLY!A12) -> 0 | AF12: =COUNTIF(TT!$D$574:$D$584,TALLY!A12) -> 0 | AG12: =COUNTIF(TT!$D$591:$D$601,TALLY!A12) -> 0 | AH12: =COUNTIF(TT!$D$608:$D$619,TALLY!A12) -> 0 | AI12: =COUNTIF(TT!$D$628:$D$647,TALLY!A12) -> 0 | AJ12: =COUNTIF(TT!$D$654:$D$668,TALLY!A12) -> 1 | AK12: =COUNTIF(TT!$D$675:$D$685,TALLY!A12) -> 0 | AL12: =COUNTIF(TT!$D$692:$D$702,TALLY!A12) -> 0 | AM12: =COUNTIF(TT!$D$709:$D$721,TALLY!A12) -> 0 | AN12: =COUNTIF(TT!$D$728:$D$737,TALLY!A12) -> 1 | AO12: =COUNTIF(TT!$D$744:$D$753,TALLY!A12) -> 0 | AP12: =COUNTIF(TT!$D$759:$D$774,TALLY!A12) -> 0 | AQ12: =COUNTIF(TT!$D$781:$D$789,TALLY!A12) -> 0 | AR12: ED1-GEOM | AS12: =SUM($B12:$D12) -> 0 | AT12: =SUM(E12:G12) -> 0 | AU12: =SUM(H12:J12) -> 1 | AV12: =SUM(K12:M12) -> 1 | AW12: =SUM(N12:P12) -> 1 | AX12: =SUM($Q12:$S12) -> 0 | AY12: =SUM(T12:V12) -> 0 | AZ12: =SUM(W12:Y12) -> 0 | BA12: =SUM(Z12:AB12) -> 1 | BB12: =SUM(AC12:AE12) -> 1 | BC12: =SUM(AF12:AH12) -> 0 | BD12: =SUM(AI12:AK12) -> 1 | BE12: =SUM(AL12:AN12) -> 1 | BF12: =SUM(AO12:AQ12) -> 0 | BG12: =SUM(AS12:BF12) -> 7
A13: ED1-IND | B13: =COUNTIF(TT!$D$6:$D$15,TALLY!A13) -> 0 | C13: =COUNTIF(TT!$D$22:$D$32,TALLY!A13) -> 0 | D13: =COUNTIF(TT!$D$39:$D$49,TALLY!A13) -> 1 | E13: =COUNTIF(TT!$D$57:$D$67,TALLY!A13) -> 0 | F13: =COUNTIF(TT!$D$74:$D$86,TALLY!A13) -> 0 | G13: =COUNTIF(TT!$D$93:$D$107,TALLY!A13) -> 0 | H13: =COUNTIF(TT!$D$113:$D$129,TALLY!A13) -> 0 | I13: =COUNTIF(TT!$D$135:$D$155,TALLY!A13) -> 0 | J13: =COUNTIF(TT!$D$162:$D$173,TALLY!A13) -> 0 | K13: =COUNTIF(TT!$D$180:$D$199,TALLY!A13) -> 1 | L13: =COUNTIF(TT!$D$207:$D$215,TALLY!A13) -> 0 | M13: =COUNTIF(TT!$D$224:$D$231,TALLY!A13) -> 0 | N13: =COUNTIF(TT!$D$237:$D$249,TALLY!A13) -> 0 | O13: =COUNTIF(TT!$D$256:$D$264,TALLY!A13) -> 0 | P13: =COUNTIF(TT!$D$271:$D$286,TALLY!A13) -> 0 | Q13: =COUNTIF(TT!$D$293:$D$300,TALLY!A13) -> 0 | R13: =COUNTIF(TT!$D$307:$D$319,TALLY!A13) -> 1 | S13: =COUNTIF(TT!$D$326:$D$334,TALLY!A13) -> 0 | T13: =COUNTIF(TT!$D$341:$D$350,TALLY!A13) -> 0 | U13: =COUNTIF(TT!$D$357:$D$366,TALLY!A13) -> 0 | V13: =COUNTIF(TT!$D$373:$D$383,TALLY!A13) -> 0 | W13: =COUNTIF(TT!$D$390:$D$405,TALLY!A13) -> 1 | X13: =COUNTIF(TT!$D$412:$D$423,TALLY!A13) -> 0 | Y13: =COUNTIF(TT!$D$430:$D$438,TALLY!A13) -> 0 | Z13: =COUNTIF(TT!$D$443:$D$457,TALLY!A13) -> 0 | AA13: =COUNTIF(TT!$D$464:$D$474,TALLY!A13) -> 0 | AB13: =COUNTIF(TT!$D$481:$D$494,TALLY!A13) -> 0 | AC13: =COUNTIF(TT!$D$503:$D$522,TALLY!A13) -> 0 | AD13: =COUNTIF(TT!$D$529:$D$541,TALLY!A13) -> 1 | AE13: =COUNTIF(TT!$D$548:$D$561,TALLY!A13) -> 0 | AF13: =COUNTIF(TT!$D$574:$D$584,TALLY!A13) -> 0 | AG13: =COUNTIF(TT!$D$591:$D$601,TALLY!A13) -> 0 | AH13: =COUNTIF(TT!$D$608:$D$619,TALLY!A13) -> 0 | AI13: =COUNTIF(TT!$D$628:$D$647,TALLY!A13) -> 0 | AJ13: =COUNTIF(TT!$D$654:$D$668,TALLY!A13) -> 1 | AK13: =COUNTIF(TT!$D$675:$D$685,TALLY!A13) -> 0 | AL13: =COUNTIF(TT!$D$692:$D$702,TALLY!A13) -> 0 | AM13: =COUNTIF(TT!$D$709:$D$721,TALLY!A13) -> 0 | AN13: =COUNTIF(TT!$D$728:$D$737,TALLY!A13) -> 0 | AO13: =COUNTIF(TT!$D$744:$D$753,TALLY!A13) -> 0 | AP13: =COUNTIF(TT!$D$759:$D$774,TALLY!A13) -> 1 | AQ13: =COUNTIF(TT!$D$781:$D$789,TALLY!A13) -> 0 | AR13: ED1-IND | AS13: =SUM($B13:$D13) -> 1 | AT13: =SUM(E13:G13) -> 0 | AU13: =SUM(H13:J13) -> 0 | AV13: =SUM(K13:M13) -> 1 | AW13: =SUM(N13:P13) -> 0 | AX13: =SUM($Q13:$S13) -> 1 | AY13: =SUM(T13:V13) -> 0 | AZ13: =SUM(W13:Y13) -> 1 | BA13: =SUM(Z13:AB13) -> 0 | BB13: =SUM(AC13:AE13) -> 1 | BC13: =SUM(AF13:AH13) -> 0 | BD13: =SUM(AI13:AK13) -> 1 | BE13: =SUM(AL13:AN13) -> 0 | BF13: =SUM(AO13:AQ13) -> 1 | BG13: =SUM(AS13:BF13) -> 7
A14: ED1-MARI | B14: =COUNTIF(TT!$D$6:$D$15,TALLY!A14) -> 0 | C14: =COUNTIF(TT!$D$22:$D$32,TALLY!A14) -> 0 | D14: =COUNTIF(TT!$D$39:$D$49,TALLY!A14) -> 0 | E14: =COUNTIF(TT!$D$57:$D$67,TALLY!A14) -> 0 | F14: =COUNTIF(TT!$D$74:$D$86,TALLY!A14) -> 0 | G14: =COUNTIF(TT!$D$93:$D$107,TALLY!A14) -> 1 | H14: =COUNTIF(TT!$D$113:$D$129,TALLY!A14) -> 0 | I14: =COUNTIF(TT!$D$135:$D$155,TALLY!A14) -> 0 | J14: =COUNTIF(TT!$D$162:$D$173,TALLY!A14) -> 0 | K14: =COUNTIF(TT!$D$180:$D$199,TALLY!A14) -> 1 | L14: =COUNTIF(TT!$D$207:$D$215,TALLY!A14) -> 0 | M14: =COUNTIF(TT!$D$224:$D$231,TALLY!A14) -> 0 | N14: =COUNTIF(TT!$D$237:$D$249,TALLY!A14) -> 0 | O14: =COUNTIF(TT!$D$256:$D$264,TALLY!A14) -> 0 | P14: =COUNTIF(TT!$D$271:$D$286,TALLY!A14) -> 0 | Q14: =COUNTIF(TT!$D$293:$D$300,TALLY!A14) -> 0 | R14: =COUNTIF(TT!$D$307:$D$319,TALLY!A14) -> 1 | S14: =COUNTIF(TT!$D$326:$D$334,TALLY!A14) -> 0 | T14: =COUNTIF(TT!$D$341:$D$350,TALLY!A14) -> 0 | U14: =COUNTIF(TT!$D$357:$D$366,TALLY!A14) -> 0 | V14: =COUNTIF(TT!$D$373:$D$383,TALLY!A14) -> 0 | W14: =COUNTIF(TT!$D$390:$D$405,TALLY!A14) -> 1 | X14: =COUNTIF(TT!$D$412:$D$423,TALLY!A14) -> 0 | Y14: =COUNTIF(TT!$D$430:$D$438,TALLY!A14) -> 0 | Z14: =COUNTIF(TT!$D$443:$D$457,TALLY!A14) -> 0 | AA14: =COUNTIF(TT!$D$464:$D$474,TALLY!A14) -> 0 | AB14: =COUNTIF(TT!$D$481:$D$494,TALLY!A14) -> 1 | AC14: =COUNTIF(TT!$D$503:$D$522,TALLY!A14) -> 1 | AD14: =COUNTIF(TT!$D$529:$D$541,TALLY!A14) -> 0 | AE14: =COUNTIF(TT!$D$548:$D$561,TALLY!A14) -> 0 | AF14: =COUNTIF(TT!$D$574:$D$584,TALLY!A14) -> 0 | AG14: =COUNTIF(TT!$D$591:$D$601,TALLY!A14) -> 0 | AH14: =COUNTIF(TT!$D$608:$D$619,TALLY!A14) -> 0 | AI14: =COUNTIF(TT!$D$628:$D$647,TALLY!A14) -> 1 | AJ14: =COUNTIF(TT!$D$654:$D$668,TALLY!A14) -> 0 | AK14: =COUNTIF(TT!$D$675:$D$685,TALLY!A14) -> 0 | AL14: =COUNTIF(TT!$D$692:$D$702,TALLY!A14) -> 0 | AM14: =COUNTIF(TT!$D$709:$D$721,TALLY!A14) -> 0 | AN14: =COUNTIF(TT!$D$728:$D$737,TALLY!A14) -> 0 | AO14: =COUNTIF(TT!$D$744:$D$753,TALLY!A14) -> 0 | AP14: =COUNTIF(TT!$D$759:$D$774,TALLY!A14) -> 1 | AQ14: =COUNTIF(TT!$D$781:$D$789,TALLY!A14) -> 0 | AR14: ED1-MARI | AS14: =SUM($B14:$D14) -> 0 | AT14: =SUM(E14:G14) -> 1 | AU14: =SUM(H14:J14) -> 0 | AV14: =SUM(K14:M14) -> 1 | AW14: =SUM(N14:P14) -> 0 | AX14: =SUM($Q14:$S14) -> 1 | AY14: =SUM(T14:V14) -> 0 | AZ14: =SUM(W14:Y14) -> 1 | BA14: =SUM(Z14:AB14) -> 1 | BB14: =SUM(AC14:AE14) -> 1 | BC14: =SUM(AF14:AH14) -> 0 | BD14: =SUM(AI14:AK14) -> 1 | BE14: =SUM(AL14:AN14) -> 0 | BF14: =SUM(AO14:AQ14) -> 1 | BG14: =SUM(AS14:BF14) -> 8
... A74: ED4-TEL | B74: =COUNTIF(TT!$D$6:$D$15,TALLY!A74) -> 0 | C74: =COUNTIF(TT!$D$22:$D$32,TALLY!A74) -> 0 | D74: =COUNTIF(TT!$D$39:$D$49,TALLY!A74) -> 0 | E74: =COUNTIF(TT!$D$57:$D$67,TALLY!A74) -> 1 | F74: =COUNTIF(TT!$D$74:$D$86,TALLY!A74) -> 0 | G74: =COUNTIF(TT!$D$93:$D$107,TALLY!A74) -> 0 | H74: =COUNTIF(TT!$D$113:$D$129,TALLY!A74) -> 0 | I74: =COUNTIF(TT!$D$135:$D$155,TALLY!A74) -> 0 | J74: =COUNTIF(TT!$D$162:$D$173,TALLY!A74) -> 1 | K74: =COUNTIF(TT!$D$180:$D$199,TALLY!A74) -> 0 | L74: =COUNTIF(TT!$D$207:$D$215,TALLY!A74) -> 0 | M74: =COUNTIF(TT!$D$224:$D$231,TALLY!A74) -> 0 | N74: =COUNTIF(TT!$D$237:$D$249,TALLY!A74) -> 0 | O74: =COUNTIF(TT!$D$256:$D$264,TALLY!A74) -> 0 | P74: =COUNTIF(TT!$D$271:$D$286,TALLY!A74) -> 0 | Q74: =COUNTIF(TT!$D$293:$D$300,TALLY!A74) -> 0 | R74: =COUNTIF(TT!$D$307:$D$319,TALLY!A74) -> 0 | S74: =COUNTIF(TT!$D$326:$D$334,TALLY!A74) -> 0 | T74: =COUNTIF(TT!$D$341:$D$350,TALLY!A74) -> 0 | U74: =COUNTIF(TT!$D$357:$D$366,TALLY!A74) -> 1 | V74: =COUNTIF(TT!$D$373:$D$383,TALLY!A74) -> 0 | W74: =COUNTIF(TT!$D$390:$D$405,TALLY!A74) -> 0 | X74: =COUNTIF(TT!$D$412:$D$423,TALLY!A74) -> 0 | Y74: =COUNTIF(TT!$D$430:$D$438,TALLY!A74) -> 0 | Z74: =COUNTIF(TT!$D$443:$D$457,TALLY!A74) -> 0 | AA74: =COUNTIF(TT!$D$464:$D$474,TALLY!A74) -> 0 | AB74: =COUNTIF(TT!$D$481:$D$494,TALLY!A74) -> 0 | AC74: =COUNTIF(TT!$D$503:$D$522,TALLY!A74) -> 0 | AD74: =COUNTIF(TT!$D$529:$D$541,TALLY!A74) -> 0 | AE74: =COUNTIF(TT!$D$548:$D$561,TALLY!A74) -> 0 | AF74: =COUNTIF(TT!$D$574:$D$584,TALLY!A74) -> 0 | AG74: =COUNTIF(TT!$D$591:$D$601,TALLY!A74) -> 0 | AH74: =COUNTIF(TT!$D$608:$D$619,TALLY!A74) -> 1 | AI74: =COUNTIF(TT!$D$628:$D$647,TALLY!A74) -> 0 | AJ74: =COUNTIF(TT!$D$654:$D$668,TALLY!A74) -> 1 | AK74: =COUNTIF(TT!$D$675:$D$685,TALLY!A74) -> 0 | AL74: =COUNTIF(TT!$D$692:$D$702,TALLY!A74) -> 0 | AM74: =COUNTIF(TT!$D$709:$D$721,TALLY!A74) -> 0 | AN74: =COUNTIF(TT!$D$728:$D$737,TALLY!A74) -> 1 | AO74: =COUNTIF(TT!$D$744:$D$753,TALLY!A74) -> 0 | AP74: =COUNTIF(TT!$D$759:$D$774,TALLY!A74) -> 0 | AQ74: =COUNTIF(TT!$D$781:$D$789,TALLY!A74) -> 0 | AR74: ED4-TEL | AS74: =SUM($B74:$D74) -> 0 | AT74: =SUM(E74:G74) -> 1 | AU74: =SUM(H74:J74) -> 1 | AV74: =SUM(K74:M74) -> 0 | AW74: =SUM(N74:P74) -> 0 | AX74: =SUM($Q74:$S74) -> 0 | AY74: =SUM(T74:V74) -> 1 | AZ74: =SUM(W74:Y74) -> 0 | BA74: =SUM(Z74:AB74) -> 0 | BB74: =SUM(AC74:AE74) -> 0 | BC74: =SUM(AF74:AH74) -> 1 | BD74: =SUM(AI74:AK74) -> 1 | BE74: =SUM(AL74:AN74) -> 1 | BF74: =SUM(AO74:AQ74) -> 0 | BG74: =SUM(AS74:BF74) -> 6
A75: Sum | B75: =SUM(B3:B74) -> 10 | C75: =SUM(C3:C74) -> 11 | D75: =SUM(D3:D74) -> 11 | E75: =SUM(E3:E74) -> 11 | F75: =SUM(F3:F74) -> 13 | G75: =SUM(G3:G74) -> 15 | H75: =SUM(H3:H74) -> 17 | I75: =SUM(I3:I74) -> 21 | ... AQ75: =SUM(AQ3:AQ74) -> 9

Sheet WATER

Sheet ROOMS
A1: College of Engineering
A2: Available Rooms
A3: Rooms | B3: Exam Capacity
A4: LT | B4: 50 | C4: COHORT A1 | D4: BAMFO KWAKYE A | E4: 2
A5: RMA | B5: 48 | E5: 1
A6: RMB | B6: 48 | E6: 1
A7: VSLA | B7: 90 | E7: 2 | F7: 474
A8: 206 | B8: 48 | C8: COHORT A2 | E8: 1
A9: 303 | B9: 60 | E9: 2
A10: 304 | B10: 40 | E10: 1
A11: N1 | B11: 50 | C11: COHORT A3 | E11: 1
A12: N2 | B12: 40 | E12: 1
A13: PB001 | B13: 80 | C13: COHORT B1 | D13: PETROLEUM BUILDING B | E13: 2
A14: PB020 | B14: 80 | E14: 2
A15: PB014 | B15: 80 | E15: 2
A16: PB012 | B16: 0 | E16: 1
A17: PB008 | B17: 60 | E17: 2
A18: PB201 | B18: 80 | C18: COHORT B2 | E18: 2
A19: PB214 | B19: 80 | E19: 2
A20: PB212 | B20: 50 | E20: 1
A21: PB208 | B21: 60 | E21: 1 | F21: =SUM(B13:B21) -> 570
A22: VCR | B22: 50 | C22: COHORT C1 | D22: EXAMS OFFICE C | E22: 1
A23: ECR | B23: 50 | E23: 1
A24: A110 | B24: 60 | E24: 2
A25: EA | B25: 60 | C25: COHORT C2 | E25: 3
A26: NAF1 | B26: 90 | E26: 2 | F26: =SUM(B22:B26) -> 310
A27: NEB-SF1 | B27: 160 | C27: COHORT D1 | D27: NEB D | E27: 3
A28: NEB-FF2 | B28: 60 | C28: COHORT D2 | E28: 2
A29: NEB-FF1 | B29: 110 | C29: COHORT D3
A30: NEB-TF | B30: 160 | E30: 2 | F30: =SUM(B27:B30) -> 490
E31: 1
A32: Total | B32: =SUM(B4:B30) -> 1844

Sheet cenG_PROJECT (2nd Sem)

Sheet Invigilation + Meals(2nd Sem)
A1: KWAME NKRUMAH UNIVERSITY OF SCIENCE AND TECHNOLOGY
A2: COLLEGE OF ENGINEERING
A3: END OF FIRST SEMESTER EXAMINATIONS 2024/2025 ACADEMIC YEAR
A4: Invigilation + Meals Reumuneration
A5: SN | B5: STAFF ID | C5: Name | D5: Status | E5: Time/hrs | F5: Rate/Hr | G5: Total Inv. Amount | H5: Meals Amount (GHC) | I5: Amt (GHC) | J5: Tax (GHC) | K5: Amt Due (GHC) | L5: Pay Status
A6: 1 | C6: OSEI TUTU DERRICK | D6: NSM/NSS/pro | E6: 14 | F6: 30 | G6: =E6*F6 -> 420 | H6: 200 | I6: =G6+H6 -> 620 | J6: =I6*0.1 -> 62 | K6: =I6*0.9 -> 558 | L6: CASH | N6: 30 | O6: 10
A7: 2 | C7: DOROTHY AGYEMANG AKUA | D7: NSM/NSS/pro | E7: 14 | F7: 30 | G7: =E7*F7 -> 420 | H7: 200 | I7: =G7+H7 -> 620 | J7: =I7*0.1 -> 62 | K7: =I7*0.9 -> 558 | L7: CASH | N7: 30 | O7: 10
A8: 3 | C8: DUFFOUR JUSTICE | D8: NSM/NSS/pro | E8: 14 | F8: 30 | G8: =E8*F8 -> 420 | H8: 200 | I8: =G8+H8 -> 620 | J8: =I8*0.1 -> 62 | K8: =I8*0.9 -> 558 | L8: CASH | N8: 30 | O8: 10
A9: 4 | C9: BRIGHT AMOAKO WIAFE | D9: NSM/NSS/pro | E9: 14 | F9: 30 | G9: =E9*F9 -> 420 | H9: 200 | I9: =G9+H9 -> 620 | J9: =I9*0.1 -> 62 | K9: =I9*0.9 -> 558 | L9: CASH | N9: 30 | O9: 10
A10: 5 | C10: ERICA TUTUWAA BAFFOE JNR. | D10: NSM/NSS/pro | E10: 14 | F10: 30 | G10: =E10*F10 -> 420 | H10: 200 | I10: =G10+H10 -> 620 | J10: =I10*0.1 -> 62 | K10: =I10*0.9 -> 558 | L10: CASH | N10: 30 | O10: 12
A11: 6 | C11: AARON GYAMFI ATOBRAH APRAKU | D11: NSM/NSS/pro | E11: 14 | F11: 30 | G11: =E11*F11 -> 420 | H11: 200 | I11: =G11+H11 -> 620 | J11: =I11*0.1 -> 62 | K11: =I11*0.9 -> 558 | L11: CASH | N11: 30 | O11: 12
A12: 7 | C12: AMPONSAH MICHAEL DARKO | D12: NSM/NSS/pro | E12: 14 | F12: 30 | G12: =E12*F12 -> 420 | H12: 200 | I12: =G12+H12 -> 620 | J12: =I12*0.1 -> 62 | K12: =I12*0.9 -> 558 | L12: CASH | N12: 30 | O12: 15
A13: 8 | C13: GIDEON SAKYI OSEW | D13: NSM/NSS/pro | E13: 14 | F13: 30 | G13: =E13*F13 -> 420 | H13: 200 | I13: =G13+H13 -> 620 | J13: =I13*0.1 -> 62 | K13: =I13*0.9 -> 558 | L13: CASH
A14: 9 | C14: KWABENA AFAAWUAH | D14: NSM/NSS/Acct | E14: 18 | F14: 30 | G14: =E14*F14 -> 540 | H14: 200 | I14: =G14+H14 -> 740 | J14: =I14*0.1 -> 74 | K14: =I14*0.9 -> 666 | L14: CASH
A15: 10 | C15: CLIFF OBIRI SEPAH | D15: NSM/NSS/Acct | E15: 25 | F15: 30 | G15: =E15*F15 -> 750 | H15: 200 | I15: =G15+H15 -> 950 | J15: =I15*0.1 -> 95 | K15: =I15*0.9 -> 855 | L15: CASH
A16: 11 | C16: BAAH-BOATENG SAMUEL | D16: NSM/NSS/Acct | E16: 18 | F16: 30 | G16: =E16*F16 -> 540 | H16: 200 | I16: =G16+H16 -> 740 | J16: =I16*0.1 -> 74 | K16: =I16*0.9 -> 666 | L16: CASH
A17: 12 | C17: NANA AGYEMANG AMOAHENE YEBOAH | D17: NSM/NSS/Audit | E17: 80 | F17: 30 | G17: =E17*F17 -> 2400 | H17: 400 | I17: =G17+H17 -> 2800 | J17: =I17*0.1 -> 280 | K17: =I17*0.9 -> 2520 | L17: CASH
A18: 13 | C18: CHRISTIAN D. BOATENG | D18: NSM/NSS/pro | E18: 30 | F18: =N18 -> 30 | G18: =E18*F18 -> 900 | H18: 200 | I18: =G18+H18 -> 1100 | J18: =I18*0.1 -> 110 | K18: =I18*0.9 -> 990 | L18: CASH | N18: 30 | O18: 10
A19: 14 | C19: JONATHAN AGYEMAN-DUAH KARIKARI | D19: SS/procur | E19: 80 | F19: =N19 -> 30 | G19: =E19*F19 -> 2400 | H19: 400 | I19: =G19+H19 -> 2800 | J19: =I19*0.1 -> 280 | K19: =I19*0.9 -> 2520 | L19: CASH | N19: 30 | O19: 12
A20: 15 | C20: IMBEAH JULIET | D20: NSM/NSS-TA-wt | E20: 75 | F20: =N20 -> 30 | G20: =E20*F20 -> 2250 | H20: 300 | I20: =G20+H20 -> 2550 | J20: =I20*0.1 -> 255 | K20: =I20*0.9 -> 2295 | L20: CASH | N20: 30
A21: 16 | C21: RUTH ATTA BENYAH | D21: NSM/NSS-TA-wt | E21: 75 | F21: =N21 -> 30 | G21: =E21*F21 -> 2250 | H21: 300 | I21: =G21+H21 -> 2550 | J21: =I21*0.1 -> 255 | K21: =I21*0.9 -> 2295 | L21: CASH | N21: 30
A22: 17 | C22: PAUL ADAZURU | D22: NSM/NSS-TA-wt | E22: 75 | F22: =N22 -> 30 | G22: =E22*F22 -> 2250 | H22: 300 | I22: =G22+H22 -> 2550 | J22: =I22*0.1 -> 255 | K22: =I22*0.9 -> 2295 | L22: CASH | N22: 30
A23: 18 | C23: OMANHENE KOFI GYIMAH | D23: NSM/NSS-TA-wt | E23: 75 | F23: 30 | G23: =E23*F23 -> 2250 | H23: 300 | I23: =G23+H23 -> 2550 | J23: =I23*0.1 -> 255 | K23: =I23*0.9 -> 2295 | L23: CASH | N23: 30
A24: 19 | C24: GARVIN KOKONU | D24: NSM/NSS-TA-wt | E24: 75 | F24: 30 | G24: =E24*F24 -> 2250 | H24: 300 | I24: =G24+H24 -> 2550 | J24: =I24*0.1 -> 255 | K24: =I24*0.9 -> 2295 | L24: CASH | N24: 30
A25: 20 | C25: MARY ADDAI | D25: NSM/NSS-nurs | E25: 130 | F25: =N25 -> 30 | G25: =E25*F25 -> 3900 | H25: 500 | I25: =G25+H25 -> 4400 | J25: =I25*0.1 -> 440 | K25: =I25*0.9 -> 3960 | L25: CASH | N25: 30 | O25: 55
A26: 21 | C26: VIVIAN DZAKA | D26: NSM/NSS-nurs | E26: 130 | F26: =N26 -> 30 | G26: =E26*F26 -> 3900 | H26: 500 | I26: =G26+H26 -> 4400 | J26: =I26*0.1 -> 440 | K26: =I26*0.9 -> 3960 | L26: CASH | N26: 30
A27: 22 | C27: Abdul-Mumin Tahiru | D27: NSM/NSS-TA | E27: 11 | F27: 30 | G27: =E27*F27 -> 330 | H27: =E27*10 -> 110 | I27: =G27+H27 -> 440 | J27: =0.1*I27 -> 44 | K27: =0.9*I27 -> 396 | L27: CASH | N27: 30 | O27: 55
A28: 23 | C28: Polycarp Bome | D28: NSM/NSS-TA | E28: 11 | F28: 30 | G28: =E28*F28 -> 330 | H28: =E28*10 -> 110 | I28: =G28+H28 -> 440 | J28: =0.1*I28 -> 44 | K28: =0.9*I28 -> 396 | L28: CASH | N28: 30 | O28: 55 | P28: 15
A29: 24 | C29: Akambisa Julius | D29: NSM/NSS-TA | E29: 9 | F29: 30 | G29: =E29*F29 -> 270 | H29: =E29*10 -> 90 | I29: =G29+H29 -> 360 | J29: =0.1*I29 -> 36 | K29: =0.9*I29 -> 324 | L29: CASH | N29: 30 | O29: 62
A30: 25 | C30: Adu Isaac Kwabena Afriyie | D30: NSM/NSS-TA | E30: 9 | F30: 30 | G30: =E30*F30 -> 270 | H30: =E30*10 -> 90 | I30: =G30+H30 -> 360 | J30: =0.1*I30 -> 36 | K30: =0.9*I30 -> 324 | L30: CASH | N30: 30 | O30: 62
A31: 26 | C31: Amissah Nana Ama | D31: NSM/NSS-TA | E31: 9 | F31: 30 | G31: =E31*F31 -> 270 | H31: =E31*10 -> 90 | I31: =G31+H31 -> 360 | J31: =0.1*I31 -> 36 | K31: =0.9*I31 -> 324 | L31: CASH | N31: 30 | O31: 62
A32: 27 | C32: Akowuah Nana Amoah | D32: NSM/NSS-TA | E32: 9 | F32: 30 | G32: =E32*F32 -> 270 | H32: =E32*10 -> 90 | I32: =G32+H32 -> 360 | J32: =0.1*I32 -> 36 | K32: =0.9*I32 -> 324 | L32: CASH | N32: 30 | O32: 10
A33: 28 | C33: Ankomah Theophilus | D33: NSM/NSS-TA | E33: 11 | F33: 30 | G33: =E33*F33 -> 330 | H33: =E33*10 -> 110 | I33: =G33+H33 -> 440 | J33: =0.1*I33 -> 44 | K33: =0.9*I33 -> 396 | L33: CASH | N33: 30 | O33: 9
A34: 29 | C34: Antwi Dennis Barima | D34: NSM/NSS-TA | E34: 6 | F34: 30 | G34: =E34*F34 -> 180 | H34: =E34*10 -> 60 | I34: =G34+H34 -> 240 | J34: =0.1*I34 -> 24 | K34: =0.9*I34 -> 216 | L34: CASH | N34: 30
A35: 30 | C35: Dzah Raymond | D35: NSM/NSS-TA | E35: 11 | F35: 30 | G35: =E35*F35 -> 330 | H35: =E35*10 -> 110 | I35: =G35+H35 -> 440 | J35: =0.1*I35 -> 44 | K35: =0.9*I35 -> 396 | L35: CASH | N35: 30 | O35: 15
A36: 31 | C36: Dadzie Emmanuel | D36: NSM/NSS-TA | E36: 9 | F36: 30 | G36: =E36*F36 -> 270 | H36: =E36*10 -> 90 | I36: =G36+H36 -> 360 | J36: =0.1*I36 -> 36 | K36: =0.9*I36 -> 324 | L36: CASH | N36: 30 | O36: 11
A37: 32 | C37: Egyir Bernard | D37: NSM/NSS-TA | E37: 9 | F37: 30 | G37: =E37*F37 -> 270 | H37: =E37*10 -> 90 | I37: =G37+H37 -> 360 | J37: =0.1*I37 -> 36 | K37: =0.9*I37 -> 324 | L37: CASH | N37: 30 | O37: 21
A38: 33 | C38: Ekuful Ebenezer | D38: NSM/NSS-TA | E38: 18 | F38: 30 | G38: =E38*F38 -> 540 | H38: =E38*10 -> 180 | I38: =G38+H38 -> 720 | J38: =0.1*I38 -> 72 | K38: =0.9*I38 -> 648 | L38: CASH | N38: 30
A39: 34 | C39: Felix Owiredu Owusu | D39: NSM/NSS-TA | E39: 11 | F39: 30 | G39: =E39*F39 -> 330 | H39: =E39*10 -> 110 | I39: =G39+H39 -> 440 | J39: =0.1*I39 -> 44 | K39: =0.9*I39 -> 396 | L39: CASH | N39: 30 | O39: 14
A40: 35 | C40: George Nii Martey Colley | D40: NSM/NSS-TA | E40: 11 | F40: 30 | G40: =E40*F40 -> 330 | H40: =E40*10 -> 110 | I40: =G40+H40 -> 440 | J40: =0.1*I40 -> 44 | K40: =0.9*I40 -> 396 | L40: CASH | N40: 30 | O40: 10
...

Sheet supp
A1: KWAME NKRUMAH UNIVERSITY OF SCIENCE AND TECHNOLOGY
A2: COLLEGE OF ENGINEERING
A3: END OF FIRST SEMESTER EXAMINATIONS 2024/2025 ACADEMIC YEAR
A4: Invigilation + Meals Reumuneration
A6: SN | B6: Name | C6: Status | D6: Time/hrs | E6: Rate/Hr | F6: Total Inv. Amount | G6: Meals Amount (GHC) | H6: Amt (GHC) | I6: Tax (GHC) | J6: Amt Due (GHC) | K6: Pay Status
A7: 1 | B7: NYARKO, KWABENA BIRITWUM | C7: SM | D7: 195 | E7: 60 | F7: =D7*E7 -> 11700 | G7: 600 | H7: =F7+G7 -> 12300 | I7: =H7*0.1 -> 1230 | J7: =H7-I7 -> 11070 | K7: PAYROLL
A8: 2 | B8: Ida Saeed | C8: SM | D8: 130 | E8: 60 | F8: =D8*E8 -> 7800 | G8: 500 | H8: =F8+G8 -> 8300 | I8: =H8*0.1 -> 830 | J8: =H8-I8 -> 7470 | K8: PAYROLL
A9: 3 | B9: OWUSU, JOHNSON | C9: SM | D9: 130 | E9: 60 | F9: =D9*E9 -> 7800 | G9: 500 | H9: =F9+G9 -> 8300 | I9: =H9*0.1 -> 830 | J9: =H9-I9 -> 7470 | K9: PAYROLL
A10: 4 | B10: EMMANUEL ASUMING FRIMPONG | C10: SM/Dean | D10: 148 | E10: 60 | F10: =D10*E10 -> 8880 | G10: 600 | H10: =F10+G10 -> 9480 | I10: =H10*0.1 -> 948 | J10: =H10-I10 -> 8532 | K10: PAYROLL
A11: 5 | B11: KEMAUSOUR FRANCIS | C11: SM/Dean | D11: 148 | E11: 60 | F11: =D11*E11 -> 8880 | G11: 600 | H11: =F11+G11 -> 9480 | I11: =H11*0.1 -> 948 | J11: =H11-I11 -> 8532 | K11: PAYROLL
A12: 6 | B12: ADJEI, KWAKU AMANING | C12: SM/Dean | D12: 148 | E12: 60 | F12: =D12*E12 -> 8880 | G12: 600 | H12: =F12+G12 -> 9480 | I12: =H12*0.1 -> 948 | J12: =H12-I12 -> 8532 | K12: PAYROLL
E13: Total (GHS) | H13: =SUM(H7:H12) -> 57340 | I13: =SUM(I7:I12) -> 5734 | J13: =SUM(J7:J12) -> 51606
B14: `
